Workbook

Sheet Budgeted_01jun
A1: Created on | D1: Fiscal Year | E1: Value TranCurr | K1: Object number | L1: Project Definition | R1: Val/COArea Crcy | U1: WBS Element | AA1: Report currency | AB1: Val.in rep.cur. | AC1: Total budget in report currency
A2: 46008 | E2: 7021000 | K2: WBS H-51I4 | L2: H-51I4 | R2: 7021000 | U2: H-51I4 | AA2: INR | AB2: 7021000 | AC2: 7021000
A3: 46021 | E3: -881000 | K3: WBS H-51I4 | L3: H-51I4 | R3: -881000 | U3: H-51I4 | AA3: INR | AB3: -881000 | AC3: -881000
A4: 46022 | E4: 437000 | K4: WBS H-51I4 | L4: H-51I4 | R4: 437000 | U4: H-51I4 | AA4: INR | AB4: 437000 | AC4: 437000
A5: 46022 | E5: 200000 | K5: WBS H-51I4 | L5: H-51I4 | R5: 200000 | U5: H-51I4 | AA5: INR | AB5: 200000 | AC5: 200000
A6: 46023 | E6: 4025000 | K6: WBS H-51I4 | L6: H-51I4 | R6: 4025000 | U6: H-51I4 | AA6: INR | AB6: 4025000 | AC6: 4025000
A7: 46023 | E7: 12625000 | K7: WBS H-51I4 | L7: H-51I4 | R7: 12625000 | U7: H-51I4 | AA7: INR | AB7: 12625000 | AC7: 12625000
A8: 46024 | E8: 14500 | K8: WBS H-51I4 | L8: H-51I4 | R8: 14500 | U8: H-51I4 | AA8: INR | AB8: 14500 | AC8: 14500
A9: 46029 | E9: 3915000 | K9: WBS H-51I4 | L9: H-51I4 | R9: 3915000 | U9: H-51I4 | AA9: INR | AB9: 3915000 | AC9: 3915000
A10: 46031 | E10: 2124000 | K10: WBS H-51I4 | L10: H-51I4 | R10: 2124000 | U10: H-51I4 | AA10: INR | AB10: 2124000 | AC10: 2124000
A11: 46045 | E11: 100000 | K11: WBS H-51I4 | L11: H-51I4 | R11: 100000 | U11: H-51I4 | AA11: INR | AB11: 100000 | AC11: 100000
A12: 46056 | E12: 800000 | K12: WBS H-51I4 | L12: H-51I4 | R12: 800000 | U12: H-51I4 | AA12: INR | AB12: 800000 | AC12: 800000
A13: 46058 | E13: 408000 | K13: WBS H-51I4 | L13: H-51I4 | R13: 408000 | U13: H-51I4 | AA13: INR | AB13: 408000 | AC13: 408000
... A27: 46122 | E27: 311030 | K27: WBS H-51I4 | L27: H-51I4 | R27: 311030 | U27: H-51I4 | AA27: INR | AB27: 311030 | AC27: 311030
E28: 3.1783771e+09
A29: 46008 | E29: 7021000 | K29: WBS H-51I4-07 | L29: H-51I4 | R29: 7021000 | U29: H-51I4-07 | AA29: INR | AB29: 7021000 | AC29: 7021000
A30: 46021 | E30: -881000 | K30: WBS H-51I4-07 | L30: H-51I4 | R30: -881000 | U30: H-51I4-07 | AA30: INR | AB30: -881000 | AC30: -881000
A31: 46022 | E31: 437000 | K31: WBS H-51I4-07 | L31: H-51I4 | R31: 437000 | U31: H-51I4-07 | AA31: INR | AB31: 437000 | AC31: 437000
A32: 46022 | E32: 200000 | K32: WBS H-51I4-07 | L32: H-51I4 | R32: 200000 | U32: H-51I4-07 | AA32: INR | AB32: 200000 | AC32: 200000
A33: 46023 | E33: 4025000 | K33: WBS H-51I4-07 | L33: H-51I4 | R33: 4025000 | U33: H-51I4-07 | AA33: INR | AB33: 4025000 | AC33: 4025000
A34: 46023 | E34: 12625000 | K34: WBS H-51I4-07 | L34: H-51I4 | R34: 12625000 | U34: H-51I4-07 | AA34: INR | AB34: 12625000 | AC34: 12625000
A35: 46024 | E35: 14500 | K35: WBS H-51I4-07 | L35: H-51I4 | R35: 14500 | U35: H-51I4-07 | AA35: INR | AB35: 14500 | AC35: 14500
A36: 46029 | E36: 3915000 | K36: WBS H-51I4-07 | L36: H-51I4 | R36: 3915000 | U36: H-51I4-07 | AA36: INR | AB36: 3915000 | AC36: 3915000
E37: 27356500
A38: 46023 | E38: 4025000 | K38: WBS H-51I4-07-01 | L38: H-51I4 | R38: 4025000 | U38: H-51I4-07-01 | AA38: INR | AB38: 4025000 | AC38: 4025000
A39: 46023 | E39: 12625000 | K39: WBS H-51I4-07-01 | L39: H-51I4 | R39: 12625000 | U39: H-51I4-07-01 | AA39: INR | AB39: 12625000 | AC39: 12625000
A40: 46029 | E40: 3915000 | K40: WBS H-51I4-07-01 | L40: H-51I4 | R40: 3915000 | U40: H-51I4-07-01 | AA40: INR | AB40: 3915000 | AC40: 3915000
E41: 20565000
A42: 46008 | E42: 7021000 | K42: WBS H-51I4-07-02 | L42: H-51I4 | R42: 7021000 | U42: H-51I4-07-02 | AA42: INR | AB42: 7021000 | AC42: 7021000
A43: 46021 | E43: -1071000 | K43: WBS H-51I4-07-02 | L43: H-51I4 | R43: -1071000 | U43: H-51I4-07-02 | AA43: INR | AB43: -1071000 | AC43: -1071000
E44: 5950000
A45: 46021 | E45: 190000 | K45: WBS H-51I4-07-04 | L45: H-51I4 | R45: 190000 | U45: H-51I4-07-04 | AA45: INR | AB45: 190000 | AC45: 190000
A46: 46022 | E46: 437000 | K46: WBS H-51I4-07-04 | L46: H-51I4 | R46: 437000 | U46: H-51I4-07-04 | AA46: INR | AB46: 437000 | AC46: 437000
A47: 46022 | E47: 200000 | K47: WBS H-51I4-07-04 | L47: H-51I4 | R47: 200000 | U47: H-51I4-07-04 | AA47: INR | AB47: 200000 | AC47: 200000
A48: 46024 | E48: 14500 | K48: WBS H-51I4-07-04 | L48: H-51I4 | R48: 14500 | U48: H-51I4-07-04 | AA48: INR | AB48: 14500 | AC48: 14500
E49: 841500
A50: 46045 | E50: 100000 | K50: WBS H-51I4-09 | L50: H-51I4 | R50: 100000 | U50: H-51I4-09 | AA50: INR | AB50: 100000 | AC50: 100000
E51: 100000
A52: 46045 | E52: 100000 | K52: WBS H-51I4-09-01 | L52: H-51I4 | R52: 100000 | U52: H-51I4-09-01 | AA52: INR | AB52: 100000 | AC52: 100000
E53: 100000
...

Sheet Actual_30 jun
A1: Company Code | B1: Document Number | C1: Document Date | D1: Ref Document Number | E1: Posting Date | F1: Created on | G1: Period | H1: Fiscal Year | I1: WBS Element | J1: Project Definition | K1: Val/COArea Crcy | M1: Cost element descr. | N1: Var.val.in rep.cur. | O1: Item | P1: Purchase order text | Q1: CO object name | R1: Cost Element | S1: Total quantity | T1: Posted unit of meas. | U1: Value Type | V1: Document type | W1: CO area currency | X1: Purchasing Document | Y1: Material | Z1: Material Description | AA1: Name | AB1: Document Header Text | AC1: Offsetting acct no. | AD1: Name of offsetting account | AE1: Plant
I2: H-51I4-09-01 | J2: H-51I4 | K2: =L2*5100 -> 5610 | L2: 1.1 | N2: 5100 | W2: INR | AE2: 51I4
I3: H-51N3-09-01 | J3: H-51N3 | K3: =L3*5100 -> 6120 | L3: 1.2 | N3: 5100 | W3: INR | AE3: 51N2
I4: H-51N3-09-01 | J4: H-51N3 | K4: =L4*5100 -> 6630 | L4: 1.3 | N4: -5100 | W4: INR | AE4: 51N2
I5: H-51N3-07-04 | J5: H-51N3 | K5: =L5*5100 -> 7140 | L5: 1.4 | N5: 14500 | W5: INR | AE5: 51N2
I6: H-6497-07-04 | J6: H-6497 | K6: =L6*5100 -> 7650 | L6: 1.5 | N6: 14500 | W6: INR | AE6: 6497
I7: H-6074-07-04 | J7: H-6074 | K7: =L7*5100 -> 8160 | L7: 1.6 | N7: 14500 | W7: INR | AE7: 6074
I8: H-6764-07-04 | J8: H-6764 | K8: =L8*5100 -> 8670 | L8: 1.7 | N8: 14500 | W8: INR | AE8: 6764
I9: H-51N2-07-04 | J9: H-51N2 | K9: =L9*5100 -> 9180 | L9: 1.8 | N9: 14500 | W9: INR | AE9: 51N2
I10: H-63A1-08-01-02 | J10: H-63A1 | K10: =L10*5100 -> 9690 | L10: 1.9 | N10: 520000 | W10: INR | AE10: 6211
I11: H-63A1-08-01-02 | J11: H-63A1 | K11: =L11*5100 -> 10200 | L11: 2 | N11: 520000 | W11: INR | AE11: 6211
I12: H-5XA2-06-03 | J12: H-5XA2 | K12: =L12*5100 -> 10710 | L12: 2.1 | N12: 7124446.1 | W12: INR | AE12: 51XA
I13: H-5XA2-06-03 | J13: H-5XA2 | K13: =L13*5100 -> 11220 | L13: 2.2 | N13: 7129203.7 | W13: INR | AE13: 51XA
... I133: H-51X9-06-02 | J133: H-51X9 | K133: =L133*5100 -> 72420 | L133: 14.2 | N133: 2403500 | W133: INR | AE133: 51X9
I134: H-5XA2-11-02 | J134: H-5XA2 | K134: =L134*5100 -> 72930 | L134: 14.3 | N134: 1114867 | W134: INR
I135: H-51X9-11-02 | J135: H-51X9 | K135: =L135*5100 -> 73440 | L135: 14.4 | N135: 699535 | W135: INR
I136: H-5XA2-06-02 | J136: H-5XA2 | K136: =L136*5100 -> 73950 | L136: 14.5 | N136: 6258600 | W136: INR | AE136: 51XA
I137: H-5XA2-06-02 | J137: H-5XA2 | K137: =L137*5100 -> 74460 | L137: 14.6 | N137: 6253850 | W137: INR | AE137: 51XA
I138: H-5XA2-06-02 | J138: H-5XA2 | K138: =L138*5100 -> 74970 | L138: 14.7 | N138: 6252900 | W138: INR | AE138: 51XA
I139: H-5XA2-06-02 | J139: H-5XA2 | K139: =L139*5100 -> 75480 | L139: 14.8 | N139: 6245300 | W139: INR | AE139: 51XA
I140: H-5XA2-06-02 | J140: H-5XA2 | K140: =L140*5100 -> 75990 | L140: 14.9 | N140: 6269525 | W140: INR | AE140: 51XA
I141: H-5XA2-06-02 | J141: H-5XA2 | K141: =L141*5100 -> 76500 | L141: 15 | N141: 2411100 | W141: INR | AE141: 51XA
I142: H-5XA2-06-02 | J142: H-5XA2 | K142: =L142*5100 -> 77010 | L142: 15.1 | N142: 6270000 | W142: INR | AE142: 51XA
I143: H-5XA1-06-04 | J143: H-5XA1 | K143: =L143*5100 -> 77520 | L143: 15.2 | N143: 874380 | W143: INR | AE143: 51XA
I144: H-5XA1-06-04 | J144: H-5XA1 | K144: =L144*5100 -> 78030 | L144: 15.3 | N144: 2486260 | W144: INR | AE144: 51XA
I145: H-5XA1-06-04 | J145: H-5XA1 | K145: =L145*5100 -> 78540 | L145: 15.4 | N145: 334502.46 | W145: INR | AE145: 51XA
I146: H-6497-09-01 | J146: H-6497 | K146: =L146*5100 -> 79050 | L146: 15.5 | N146: 6018 | W146: INR | AE146: 6497
I147: H-51N3-09-01 | J147: H-51N3 | K147: =L147*5100 -> 79560 | L147: 15.6 | N147: 5100 | W147: INR | AE147: 51N2
... I446: H-63A2-08-01-03-02 | J446: H-63A2 | K446: =L446*5100 -> 232050 | L446: 45.5 | N446: 365897.12 | W446: INR | AE446: 6211
I447: H-5XA1-06-02 | J447: H-5XA1 | K447: =L447*5100 -> 232560 | L447: 45.6 | N447: 0.18 | W447: INR
I448: H-63A1-08-01-01 | J448: H-63A1 | K448: =L448*5100 -> 233070 | L448: 45.7 | N448: 3897190 | W448: INR | AE448: 6211
I449: H-63X9-08-01-01 | J449: H-63X9 | K449: =L449*5100 -> 233580 | L449: 45.8 | N449: 2094240 | W449: INR | AE449: 6211
I450: H-5XA1-06-05 | J450: H-5XA1 | K450: =L450*5100 -> 234090 | L450: 45.9 | N450: -0.02 | W450: INR | AE450: 51XA
I451: H-63X9-08-01-02 | J451: H-63X9 | K451: =L451*5100 -> 234600 | L451: 46 | N451: 27615.82 | W451: INR | AE451: 6211
I452: H-63X9-08-01-02 | J452: H-63X9 | K452: =L452*5100 -> 235110 | L452: 46.1 | N452: 11208.78 | W452: INR | AE452: 6211
I453: H-63X9-08-01-03-01 | J453: H-63X9 | K453: =L453*5100 -> 235620 | L453: 46.2 | N453: 54997.8 | W453: INR | AE453: 6211
I454: H-63X9-08-01-03-01 | J454: H-63X9 | K454: =L454*5100 -> 236130 | L454: 46.3 | N454: 223669 | W454: INR | AE454: 6211
I455: H-63X9-08-01-03-01 | J455: H-63X9 | K455: =L455*5100 -> 236640 | L455: 46.4 | N455: 3340803 | W455: INR | AE455: 6211
I456: H-63X9-08-01-03-01 | J456: H-63X9 | K456: =L456*5100 -> 237150 | L456: 46.5 | N456: 162878.63 | W456: INR | AE456: 6211
I457: H-63X9-08-01-03-01 | J457: H-63X9 | K457: =L457*5100 -> 237660 | L457: 46.6 | N457: 57132 | W457: INR | AE457: 6211
...

Sheet Commited_30 Jun
A1: Company Code | B1: Reference document category | C1: Document Date | D1: Object | E1: CO object name | F1: Reference item | G1: Name | H1: WBS Element | I1: Val/COArea Crcy | K1: Ref Document Number | L1: Quantity/plan | M1: Plan/COCurrency | N1: Total Quantity | O1: Transaction Currency | P1: Value TranCurr | Q1: Unit of Measure | R1: Cost element descr. | S1: Deletion Indicator | T1: Supplier | U1: User Name | V1: Acct assgnmnt number | W1: Business Transaction | X1: Cost element | Y1: Cost element name | Z1: Debit date | AA1: Dr/Cr indicator | AB1: Exchange Rate | AC1: Fiscal Year | AD1: Ledger | AE1: Material | AF1: Material Description | AG1: Period | AH1: Project Definition | AI1: Deadline item | AJ1: Material Group | AK1: Object Currency | AL1: Object type | AM1: Object type | AN1: Plan Val. RCrcy | AO1: Plan/ObjectCur. | AP1: Plan/TC | AQ1: Reference doc. type | AR1: Report currency | AS1: Val.in rep.cur. | AT1: Value in Obj. Crcy | AU1: Value Type | AV1: Version | AW1: Trading partner
D2: H-63A2-08-01-03-02 | H2: H-63A2-08-01-03-02 | I2: =J2*4129564.5 -> 4542521 | J2: 1.1 | L2: 96 | M2: 8208000 | AN2: 8208000 | AO2: 8208000 | AP2: 8208000 | AR2: INR | AS2: 4129564.5 | AT2: 4129564.5 | AU2: 21 | AV2: 0
D3: H-63A2-08-01-03-02 | H3: H-63A2-08-01-03-02 | I3: =J3*4129564.5 -> 4955477.4 | J3: 1.2 | L3: 12.96 | M3: 1360800 | AN3: 1360800 | AO3: 1360800 | AP3: 1360800 | AR3: INR | AS3: 765345 | AT3: 765345 | AU3: 21 | AV3: 0
D4: H-63A2-08-01-03-02 | H4: H-63A2-08-01-03-02 | I4: =J4*4129564.5 -> 5368433.9 | J4: 1.3 | L4: 9.6 | M4: 1728000 | AN4: 1728000 | AO4: 1728000 | AP4: 1728000 | AR4: INR | AS4: 521820 | AT4: 521820 | AU4: 21 | AV4: 0
D5: H-63A2-08-01-03-02 | H5: H-63A2-08-01-03-02 | I5: =J5*4129564.5 -> 5781390.3 | J5: 1.4 | L5: 10971.36 | M5: 8886801.6 | AN5: 8886801.6 | AO5: 8886801.6 | AP5: 8886801.6 | AR5: INR | AS5: 61041.6 | AT5: 61041.6 | AU5: 21 | AV5: 0
D6: H-63A2-08-01-03-02 | H6: H-63A2-08-01-03-02 | I6: =J6*4129564.5 -> 6194346.8 | J6: 1.5 | L6: 43.2 | M6: 5832000 | AN6: 5832000 | AO6: 5832000 | AP6: 5832000 | AR6: INR | AS6: 3720195 | AT6: 3720195 | AU6: 21 | AV6: 0
D7: H-63X9-08-01-05-02 | H7: H-63X9-08-01-05-02 | I7: =J7*4129564.5 -> 6607303.2 | J7: 1.6 | L7: 8 | M7: 788000 | AN7: 788000 | AO7: 788000 | AP7: 788000 | AR7: INR | AS7: 788000 | AT7: 788000 | AU7: 21 | AV7: 0
D8: H-63X9-08-01-05-02 | H8: H-63X9-08-01-05-02 | I8: =J8*4129564.5 -> 7020259.6 | J8: 1.7 | L8: 90 | M8: 82800 | AN8: 82800 | AO8: 82800 | AP8: 82800 | AR8: INR | AS8: 78604.8 | AT8: 78604.8 | AU8: 21 | AV8: 0
D9: H-63X9-08-01-05-02 | H9: H-63X9-08-01-05-02 | I9: =J9*4129564.5 -> 7433216.1 | J9: 1.8 | L9: 225 | M9: 191250 | AN9: 191250 | AO9: 191250 | AP9: 191250 | AR9: INR | AS9: 169830 | AT9: 169830 | AU9: 21 | AV9: 0
D10: H-63X9-08-01-03-02 | H10: H-63X9-08-01-03-02 | I10: =J10*4129564.5 -> 7846172.5 | J10: 1.9 | L10: 9 | M10: 886500 | AN10: 886500 | AO10: 886500 | AP10: 886500 | AR10: INR | AS10: 886500 | AT10: 886500 | AU10: 21 | AV10: 0
D11: H-63X9-08-01-03-02 | H11: H-63X9-08-01-03-02 | I11: =J11*4129564.5 -> 8259129 | J11: 2 | L11: 60 | M11: 5130000 | AN11: 5130000 | AO11: 5130000 | AP11: 5130000 | AR11: INR | AS11: 2479927.5 | AT11: 2479927.5 | AU11: 21 | AV11: 0
D12: H-63X9-08-01-03-02 | H12: H-63X9-08-01-03-02 | I12: =J12*4129564.5 -> 8672085.5 | J12: 2.1 | L12: 126.9 | M12: 12499650 | AN12: 12499650 | AO12: 12499650 | AP12: 12499650 | AR12: INR | AS12: 716095 | AT12: 716095 | AU12: 21 | AV12: 0
D13: H-63X9-08-01-03-02 | H13: H-63X9-08-01-03-02 | I13: =J13*4129564.5 -> 9085041.9 | J13: 2.2 | L13: 8.1 | M13: 850500 | AN13: 850500 | AO13: 850500 | AP13: 850500 | AR13: INR | AS13: 314790 | AT13: 314790 | AU13: 21 | AV13: 0
... D467: H-63WD-06-06 | H467: H-63WD-06-06 | I467: =J467*4129564.5 -> 1.9656727e+08 | J467: 47.6 | L467: 1 | M467: 2062260 | AN467: 2062260 | AO467: 2062260 | AP467: 2062260 | AR467: INR | AS467: 72542 | AT467: 72542 | AU467: 21 | AV467: 0
I468: =J468*4129564.5 -> 1.9698023e+08 | J468: 47.7 | M468: 1.0716705e+10 | O468: INR | P468: 7.9075076e+09 | AN468: 1.0716705e+10 | AR468: INR
I469: =J469*4129564.5 -> 1.9739318e+08 | J469: 47.8 | O469: USD | P469: 15394668
D470: H-5XA1-03-01 | H470: H-5XA1-03-01 | I470: =J470*4129564.5 -> 1.9780614e+08 | J470: 47.9 | L470: 1 | M470: 125000000 | N470: 0.5 | O470: INR | P470: 62500000 | Q470: SET | R470: Stock of Project Material-Domestic | T470: 123467 | U470: WF-BATCH | V470: 1 | W470: RMBE | X470: 12211000 | Y470: Stk of Prj Mat-Dom | Z470: 46387 | AA470: D | AB470: 1.00000 | AC470: 2026 | AD470: 0 | AE470: 9922310642 | AF470: ENERGY MANAGEMENT SYSTEM | AG470: 9 | AH470: H-5XA1 | AI470: 1 | AJ470: 9922 | AK470: INR | AL470: WBS element | AM470: WBS | AN470: 125000000 | AO470: 125000000 | AP470: 125000000 | AQ470: P | AR470: INR | AS470: 62500000 | AT470: 62500000 | AU470: 22 | AV470: 0
D471: H-5XA2-04 | H471: H-5XA2-04 | I471: =J471*4129564.5 -> 1.982191e+08 | J471: 48 | L471: 48 | M471: 793711056 | N471: 1 | O471: INR | P471: 1718676 | Q471: EA | R471: Stock of Project Material-Domestic | T471: 232077 | U471: 30215701 | V471: 1 | W471: RMBE | X471: 12211000 | Y471: Stk of Prj Mat-Dom | Z471: 46203 | AA471: D | AB471: 1.00000 | AC471: 2026 | AD471: 0 | AE471: 6542020464 | AF471: TRANSFORMER,CONVERTER DUTY,18/20MVA | AG471: 3 | AH471: H-5XA2 | AI471: 1 | AJ471: 6542 | AK471: INR | AL471: WBS element | AM471: WBS | AN471: 793711056 | AO471: 793711056 | AP471: 793711056 | AQ471: P | AR471: INR | AS471: 1718676 | AT471: 1718676 | AU471: 22 | AV471: 0
D472: H-5XA2-04 | H472: H-5XA2-04 | I472: =J472*4129564.5 -> 1.9863205e+08 | J472: 48.1 | L472: 3 | M472: 30000 | N472: 3 | O472: INR | P472: 30000 | Q472: EA | R472: Stock of Project Material-Domestic | T472: 232077 | U472: WF-BATCH | V472: 1 | W472: RMBE | X472: 12211000 | Y472: Stk of Prj Mat-Dom | Z472: 46203 | AA472: D | AB472: 1.00000 | AC472: 2026 | AD472: 0 | AE472: 6542300273 | AF472: BUSHING,ELECTRICAL,ABB SWEDEN,400V,40A | AG472: 3 | AH472: H-5XA2 | AI472: 1 | AJ472: 6542 | AK472: INR | AL472: WBS element | AM472: WBS | AN472: 30000 | AO472: 30000 | AP472: 30000 | AQ472: P | AR472: INR | AS472: 30000 | AT472: 30000 | AU472: 22 | AV472: 0
D473: H-5XA2-04 | H473: H-5XA2-04 | I473: =J473*4129564.5 -> 1.9904501e+08 | J473: 48.2 | L473: 3 | M473: 75000 | N473: 3 | O473: INR | P473: 75000 | Q473: EA | R473: Stock of Project Material-Domestic | T473: 232077 | U473: WF-BATCH | V473: 1 | W473: RMBE | X473: 12211000 | Y473: Stk of Prj Mat-Dom | Z473: 46203 | AA473: D | AB473: 1.00000 | AC473: 2026 | AD473: 0 | AE473: 9922153193 | AF473: LV BUSHINGS WITH METAL PARTS | AG473: 3 | AH473: H-5XA2 | AI473: 1 | AJ473: 6791 | AK473: INR | AL473: WBS element | AM473: WBS | AN473: 75000 | AO473: 75000 | AP473: 75000 | AQ473: P | AR473: INR | AS473: 75000 | AT473: 75000 | AU473: 22 | AV473: 0
D474: H-5XA2-04 | H474: H-5XA2-04 | I474: =J474*4129564.5 -> 1.9945797e+08 | J474: 48.3 | L474: 2 | M474: 36000 | N474: 2 | O474: INR | P474: 36000 | Q474: SET | R474: Stock of Project Material-Domestic | T474: 232077 | U474: WF-BATCH | V474: 1 | W474: RMBE | X474: 12211000 | Y474: Stk of Prj Mat-Dom | Z474: 46203 | AA474: D | AB474: 1.00000 | AC474: 2026 | AD474: 0 | AE474: 5999979843 | AF474: INDICATOR,TEMP,PN:6005AHX,SCIECONT | AG474: 3 | AH474: H-5XA2 | AI474: 1 | AJ474: 6002 | AK474: INR | AL474: WBS element | AM474: WBS | AN474: 36000 | AO474: 36000 | AP474: 36000 | AQ474: P | AR474: INR | AS474: 36000 | AT474: 36000 | AU474: 22 | AV474: 0
D475: H-5XA2-04 | H475: H-5XA2-04 | I475: =J475*4129564.5 -> 1.9987092e+08 | J475: 48.4 | L475: 4 | M475: 72000 | N475: 4 | O475: INR | P475: 72000 | Q475: EA | R475: Stock of Project Material-Domestic | T475: 232077 | U475: WF-BATCH | V475: 1 | W475: RMBE | X475: 12211000 | Y475: Stk of Prj Mat-Dom | Z475: 46203 | AA475: D | AB475: 1.00000 | AC475: 2026 | AD475: 0 | AE475: 5999977643 | AF475: WINDING TEMPERATURE INDICATOR | AG475: 3 | AH475: H-5XA2 | AI475: 1 | AJ475: 6542 | AK475: INR | AL475: WBS element | AM475: WBS | AN475: 72000 | AO475: 72000 | AP475: 72000 | AQ475: P | AR475: INR | AS475: 72000 | AT475: 72000 | AU475: 22 | AV475: 0
D476: H-5XA2-04 | H476: H-5XA2-04 | I476: =J476*4129564.5 -> 2.0028388e+08 | J476: 48.5 | L476: 1 | M476: 85000 | N476: 1 | O476: INR | P476: 85000 | Q476: SET | R476: Stock of Project Material-Domestic | T476: 232077 | U476: WF-BATCH | V476: 1 | W476: RMBE | X476: 12211000 | Y476: Stk of Prj Mat-Dom | Z476: 46203 | AA476: D | AB476: 1.00000 | AC476: 2026 | AD476: 0 | AE476: 9922435153 | AF476: VALVE SET | AG476: 3 | AH476: H-5XA2 | AI476: 1 | AJ476: 7787 | AK476: INR | AL476: WBS element | AM476: WBS | AN476: 85000 | AO476: 85000 | AP476: 85000 | AQ476: P | AR476: INR | AS476: 85000 | AT476: 85000 | AU476: 22 | AV476: 0
D477: H-5XA2-04 | H477: H-5XA2-04 | I477: =J477*4129564.5 -> 2.0069683e+08 | J477: 48.6 | L477: 2 | M477: 5000 | N477: 2 | O477: INR | P477: 5000 | Q477: EA | R477: Stock of Project Material-Domestic | T477: 232077 | U477: WF-BATCH | V477: 1 | W477: RMBE | X477: 12211000 | Y477: Stk of Prj Mat-Dom | Z477: 46203 | AA477: D | AB477: 1.00000 | AC477: 2026 | AD477: 0 | AE477: 5999977633 | AF477: DIAL TYPE THERMOMETER | AG477: 3 | AH477: H-5XA2 | AI477: 1 | AJ477: 6789 | AK477: INR | AL477: WBS element | AM477: WBS | AN477: 5000 | AO477: 5000 | AP477: 5000 | AQ477: P | AR477: INR | AS477: 5000 | AT477: 5000 | AU477: 22 | AV477: 0
D478: H-5XA2-04 | H478: H-5XA2-04 | I478: =J478*4129564.5 -> 2.0110979e+08 | J478: 48.7 | L478: 2 | M478: 17000 | N478: 2 | O478: INR | P478: 17000 | Q478: NO | R478: Stock of Project Material-Domestic | T478: 232077 | U478: WF-BATCH | V478: 1 | W478: RMBE | X478: 12211000 | Y478: Stk of Prj Mat-Dom | Z478: 46203 | AA478: D | AB478: 1.00000 | AC478: 2026 | AD478: 0 | AE478: 9922130013 | AF478: GAUGE,MAGNETIC OIL LEVEL | AG478: 3 | AH478: H-5XA2 | AI478: 1 | AJ478: 6789 | AK478: INR | AL478: WBS element | AM478: WBS | AN478: 17000 | AO478: 17000 | AP478: 17000 | AQ478: P | AR478: INR | AS478: 17000 | AT478: 17000 | AU478: 22 | AV478: 0
D479: H-5XA2-04 | H479: H-5XA2-04 | I479: =J479*4129564.5 -> 2.0152275e+08 | J479: 48.8 | L479: 10 | M479: 60000 | N479: 10 | O479: INR | P479: 60000 | Q479: EA | R479: Stock of Project Material-Domestic | T479: 232077 | U479: WF-BATCH | V479: 1 | W479: RMBE | X479: 12211000 | Y479: Stk of Prj Mat-Dom | Z479: 46203 | AA479: D | AB479: 1.00000 | AC479: 2026 | AD479: 0 | AE479: 9922035603 | AF479: SILICA GEL BREATHER | AG479: 3 | AH479: H-5XA2 | AI479: 1 | AJ479: 7787 | AK479: INR | AL479: WBS element | AM479: WBS | AN479: 60000 | AO479: 60000 | AP479: 60000 | AQ479: P | AR479: INR | AS479: 60000 | AT479: 60000 | AU479: 22 | AV479: 0
D480: H-5XA2-04 | H480: H-5XA2-04 | I480: =J480*4129564.5 -> 2.019357e+08 | J480: 48.9 | L480: 2 | M480: 130000 | N480: 2 | O480: INR | P480: 130000 | Q480: EA | R480: Stock of Project Material-Domestic | T480: 232077 | U480: WF-BATCH | V480: 1 | W480: RMBE | X480: 12211000 | Y480: Stk of Prj Mat-Dom | Z480: 46203 | AA480: D | AB480: 1.00000 | AC480: 2026 | AD480: 0 | AE480: 1104080066 | AF480: GASKET SET,PN:02937594,JLG | AG480: 3 | AH480: H-5XA2 | AI480: 1 | AJ480: 1104 | AK480: INR | AL480: WBS element | AM480: WBS | AN480: 130000 | AO480: 130000 | AP480: 130000 | AQ480: P | AR480: INR | AS480: 130000 | AT480: 130000 | AU480: 22 | AV480: 0
D481: H-5XA2-04 | H481: H-5XA2-04 | I481: =J481*4129564.5 -> 2.0234866e+08 | J481: 49 | L481: 2 | M481: 17000 | N481: 2 | O481: INR | P481: 17000 | Q481: EA | R481: Stock of Project Material-Domestic | T481: 232077 | U481: WF-BATCH | V481: 1 | W481: RMBE | X481: 12211000 | Y481: Stk of Prj Mat-Dom | Z481: 46203 | AA481: D | AB481: 1.00000 | AC481: 2026 | AD481: 0 | AE481: 9922035623 | AF481: BUCHHOLZ RELAY | AG481: 3 | AH481: H-5XA2 | AI481: 1 | AJ481: 6781 | AK481: INR | AL481: WBS element | AM481: WBS | AN481: 17000 | AO481: 17000 | AP481: 17000 | AQ481: P | AR481: INR | AS481: 17000 | AT481: 17000 | AU481: 22 | AV481: 0
... D819: H-63WF-08-01-06-01 | H819: H-63WF-08-01-06-01 | I819: =J819*4129564.5 -> 3.4192794e+08 | J819: 82.8 | L819: 4 | M819: 222680 | N819: 4 | O819: INR | P819: 222680 | Q819: EA | R819: Stock of Project Material-Domestic | T819: 254711 | U819: RCSL10061 | V819: 1 | W819: RMBE | X819: 12211000 | Y819: Stk of Prj Mat-Dom | Z819: 46188 | AA819: D | AB819: 1.00000 | AC819: 2026 | AD819: 0 | AE819: 9922540001 | AF819: PERFORATED PRECAST SQUARE COVER | AG819: 3 | AH819: H-63WF | AI819: 1 | AJ819: 8080 | AK819: INR | AL819: WBS element | AM819: WBS | AN819: 222680 | AO819: 222680 | AP819: 222680 | AQ819: P | AR819: INR | AS819: 222680 | AT819: 222680 | AU819: 22 | AV819: 0
D820: H-63WD-08-01-01 | H820: H-63WD-08-01-01 | I820: =J820*4129564.5 -> 3.423409e+08 | J820: 82.9 | L820: 448 | M820: 31744384 | N820: 231 | O820: INR | P820: 16368198 | Q820: EA | R820: Stock of Project Material-Domestic | T820: 265604 | U820: 30213786 | V820: 1 | W820: RMBE | X820: 12211000 | Y820: Stk of Prj Mat-Dom | Z820: 46218 | AA820: D | AB820: 1.00000 | AC820: 2026 | AD820: 0 | AE820: 9911370443 | AF820: SUPPLY OF BEAM | AG820: 4 | AH820: H-63WD | AI820: 1 | AJ820: 7890 | AK820: INR | AL820: WBS element | AM820: WBS | AN820: 31744384 | AO820: 31744384 | AP820: 31744384 | AQ820: P | AR820: INR | AS820: 16368198 | AT820: 16368198 | AU820: 22 | AV820: 0 | AW820: 58C0
D821: H-63X9-08-01-01 | H821: H-63X9-08-01-01 | I821: =J821*4129564.5 -> 3.4275385e+08 | J821: 83 | L821: 240 | M821: 16753920 | N821: 2 | O821: INR | P821: 139616.2 | Q821: EA | R821: Stock of Project Material-Domestic | T821: 265604 | U821: RCSL10061 | V821: 1 | W821: RMBE | X821: 12211000 | Y821: Stk of Prj Mat-Dom | Z821: 46218 | AA821: D | AB821: 1.00000 | AC821: 2026 | AD821: 0 | AE821: 9911370443 | AF821: SUPPLY OF BEAM | AG821: 4 | AH821: H-63X9 | AI821: 1 | AJ821: 7890 | AK821: INR | AL821: WBS element | AM821: WBS | AN821: 16753920 | AO821: 16753920 | AP821: 16753920 | AQ821: P | AR821: INR | AS821: 139616.2 | AT821: 139616.2 | AU821: 22 | AV821: 0 | AW821: 58C0
D822: H-63WG-08-01-02 | H822: H-63WG-08-01-02 | I822: =J822*4129564.5 -> 3.4316681e+08 | J822: 83.1 | L822: 27 | M822: 7020000 | N822: 11 | O822: INR | P822: 2860000 | Q822: EA | R822: Stock of Project Material-Domestic | T822: 254496 | U822: WF-BATCH | V822: 1 | W822: RMBE | X822: 12211000 | Y822: Stk of Prj Mat-Dom | Z822: 46188 | AA822: D | AB822: 1.00000 | AC822: 2026 | AD822: 0 | AE822: 9922139723 | AF822: OIL STORAGE TANK | AG822: 3 | AH822: H-63WG | AI822: 1 | AJ822: 6190 | AK822: INR | AL822: WBS element | AM822: WBS | AN822: 7020000 | AO822: 7020000 | AP822: 7020000 | AQ822: P | AR822: INR | AS822: 2860000 | AT822: 2860000 | AU822: 22 | AV822: 0
D823: H-63WF-08-01-02 | H823: H-63WF-08-01-02 | I823: =J823*4129564.5 -> 3.4357977e+08 | J823: 83.2 | L823: 11 | M823: 3080000 | N823: 11 | O823: INR | P823: 3080000 | Q823: EA | R823: Stock of Project Material-Domestic | T823: 254496 | U823: WF-BATCH | V823: 1 | W823: RMBE | X823: 12211000 | Y823: Stk of Prj Mat-Dom | Z823: 46188 | AA823: D | AB823: 1.00000 | AC823: 2026 | AD823: 0 | AE823: 9922139723 | AF823: OIL STORAGE TANK | AG823: 3 | AH823: H-63WF | AI823: 1 | AJ823: 6190 | AK823: INR | AL823: WBS element | AM823: WBS | AN823: 3080000 | AO823: 3080000 | AP823: 3080000 | AQ823: P | AR823: INR | AS823: 3080000 | AT823: 3080000 | AU823: 22 | AV823: 0
D824: H-63WD-08-01-02 | H824: H-63WD-08-01-02 | I824: =J824*4129564.5 -> 3.4399272e+08 | J824: 83.3 | L824: 28 | M824: 7280000 | N824: 28 | O824: INR | P824: 7280000 | Q824: EA | R824: Stock of Project Material-Domestic | T824: 254496 | U824: WF-BATCH | V824: 1 | W824: RMBE | X824: 12211000 | Y824: Stk of Prj Mat-Dom | Z824: 46188 | AA824: D | AB824: 1.00000 | AC824: 2026 | AD824: 0 | AE824: 9922139723 | AF824: OIL STORAGE TANK | AG824: 3 | AH824: H-63WD | AI824: 1 | AJ824: 6190 | AK824: INR | AL824: WBS element | AM824: WBS | AN824: 7280000 | AO824: 7280000 | AP824: 7280000 | AQ824: P | AR824: INR | AS824: 7280000 | AT824: 7280000 | AU824: 22 | AV824: 0
D825: H-63A1-08-01-02 | H825: H-63A1-08-01-02 | I825: =J825*4129564.5 -> 3.4440568e+08 | J825: 83.4 | L825: 18 | M825: 4680000 | N825: 6 | O825: INR | P825: 1560000 | Q825: EA | R825: Stock of Project Material-Domestic | T825: 254496 | U825: AUTO10039 | V825: 1 | W825: RMBE | X825: 12211000 | Y825: Stk of Prj Mat-Dom | Z825: 46188 | AA825: D | AB825: 1.00000 | AC825: 2026 | AD825: 0 | AE825: 9922139723 | AF825: OIL STORAGE TANK | AG825: 3 | AH825: H-63A1 | AI825: 1 | AJ825: 6190 | AK825: INR | AL825: WBS element | AM825: WBS | AN825: 4680000 | AO825: 4680000 | AP825: 4680000 | AQ825: P | AR825: INR | AS825: 1560000 | AT825: 1560000 | AU825: 22 | AV825: 0
D826: H-63A2-08-01-02 | H826: H-63A2-08-01-02 | I826: =J826*4129564.5 -> 3.4481864e+08 | J826: 83.5 | L826: 23 | M826: 5980000 | N826: 14 | O826: INR | P826: 3640000 | Q826: EA | R826: Stock of Project Material-Domestic | T826: 254496 | U826: AUTO10039 | V826: 1 | W826: RMBE | X826: 12211000 | Y826: Stk of Prj Mat-Dom | Z826: 46188 | AA826: D | AB826: 1.00000 | AC826: 2026 | AD826: 0 | AE826: 9922139723 | AF826: OIL STORAGE TANK | AG826: 3 | AH826: H-63A2 | AI826: 1 | AJ826: 6190 | AK826: INR | AL826: WBS element | AM826: WBS | AN826: 5980000 | AO826: 5980000 | AP826: 5980000 | AQ826: P | AR826: INR | AS826: 3640000 | AT826: 3640000 | AU826: 22 | AV826: 0
D827: H-5XA1-06-02 | H827: H-5XA1-06-02 | I827: =J827*4129564.5 -> 3.4523159e+08 | J827: 83.6 | L827: 100000 | M827: 47500000 | N827: 83392 | O827: INR | P827: 39611200 | Q827: M | R827: Stock of Project Material-Domestic | T827: 109921 | U827: NEEC211121 | V827: 1 | W827: RMBE | X827: 12211000 | Y827: Stk of Prj Mat-Dom | Z827: 46203 | AA827: D | AB827: 1.00000 | AC827: 2026 | AD827: 0 | AE827: 6843021273 | AF827: CABLE,ELE,ARMRD,3.3KV,AL,XLPE,1C,400MM2 | AG827: 3 | AH827: H-5XA1 | AI827: 2 | AJ827: 6877 | AK827: INR | AL827: WBS element | AM827: WBS | AN827: 47500000 | AO827: 47500000 | AP827: 47500000 | AQ827: P | AR827: INR | AS827: 39611200 | AT827: 39611200 | AU827: 22 | AV827: 0
D828: H-5XA1-06-02 | H828: H-5XA1-06-02 | I828: =J828*4129564.5 -> 3.4564455e+08 | J828: 83.7 | L828: 200000 | M828: 95000000 | N828: 200000 | O828: INR | P828: 95000000 | Q828: M | R828: Stock of Project Material-Domestic | T828: 109921 | U828: NEEC211121 | V828: 1 | W828: RMBE | X828: 12211000 | Y828: Stk of Prj Mat-Dom | Z828: 46203 | AA828: D | AB828: 1.00000 | AC828: 2026 | AD828: 0 | AE828: 6843021273 | AF828: CABLE,ELE,ARMRD,3.3KV,AL,XLPE,1C,400MM2 | AG828: 3 | AH828: H-5XA1 | AI828: 3 | AJ828: 6877 | AK828: INR | AL828: WBS element | AM828: WBS | AN828: 95000000 | AO828: 95000000 | AP828: 95000000 | AQ828: P | AR828: INR | AS828: 95000000 | AT828: 95000000 | AU828: 22 | AV828: 0
D829: H-5XA1-06-02 | H829: H-5XA1-06-02 | I829: =J829*4129564.5 -> 3.4605751e+08 | J829: 83.8 | L829: 200000 | M829: 95000000 | N829: 200000 | O829: INR | P829: 95000000 | Q829: M | R829: Stock of Project Material-Domestic | T829: 109921 | U829: NEEC211121 | V829: 1 | W829: RMBE | X829: 12211000 | Y829: Stk of Prj Mat-Dom | Z829: 46203 | AA829: D | AB829: 1.00000 | AC829: 2026 | AD829: 0 | AE829: 6843021273 | AF829: CABLE,ELE,ARMRD,3.3KV,AL,XLPE,1C,400MM2 | AG829: 3 | AH829: H-5XA1 | AI829: 4 | AJ829: 6877 | AK829: INR | AL829: WBS element | AM829: WBS | AN829: 95000000 | AO829: 95000000 | AP829: 95000000 | AQ829: P | AR829: INR | AS829: 95000000 | AT829: 95000000 | AU829: 22 | AV829: 0
D830: H-5XA1-06-02 | H830: H-5XA1-06-02 | I830: =J830*4129564.5 -> 3.4647046e+08 | J830: 83.9 | L830: 25000 | M830: 29775000 | N830: 11801 | O830: INR | P830: 14054991 | Q830: M | R830: Stock of Project Material-Domestic | T830: 109921 | U830: NEEC211121 | V830: 1 | W830: RMBE | X830: 12211000 | Y830: Stk of Prj Mat-Dom | Z830: 46203 | AA830: D | AB830: 1.00000 | AC830: 2026 | AD830: 0 | AE830: 6843021663 | AF830: CABLE,1.1KV,3.5CX300MM2,AL,XLPE,A2XFY | AG830: 3 | AH830: H-5XA1 | AI830: 2 | AJ830: 6877 | AK830: INR | AL830: WBS element | AM830: WBS | AN830: 29775000 | AO830: 29775000 | AP830: 29775000 | AQ830: P | AR830: INR | AS830: 14054991 | AT830: 14054991 | AU830: 22 | AV830: 0
...

Sheet PSS 12_CAPEX 
A1: PSS-12: 960 MW/ 1926 MWH (Installed DC)/ 865 MWH (Dispatchable AC)
A2: Capex NFA Summary
A3: Sr No | B3: Description | C3: Proposed Capex Cost for PSS-12 | H3: Remarks (All costs provided below are on basis of MWH dispatchable AC)
C4: DC Installed MW | D4: DC Dispatchable MW | E4: AC Dispatachble MWH | F4: DC Installed MWH | G4: AC Dispatachble MWH
C5: 960 | D5: 982.4019 | E5: 1964.8038 | F5: 2167.4035 | G5: 1964.8038
C6: (INR-Cr) Individual Basic Value | D6: (INR-Cr) Individual Basic Value | E6: Rs. Lacs/ MWH | F6: Rs. Lacs/ MWH | G6: USD/kWh
A7: 1 | B7: Battery Containers (2 Hour system) | C7: 1538.6691 | D7: 1.5662318 | E7: 78.31159 | F7: 70.991354 | G7: 84.203661 | H7: Total Capacity 960 MW/1926MWh- 384 Nos of Container > Basic Cost USD 55/KWh (Present regulation of 9% Export VAT refund in China to BESS OEMs is expected to be withdrawn from 01-Jan-2026. This could result in corresponding increase in BESS prices). > Logistics Cost: USD 0.95/kWh > BCD Cost @ 8.25% as per PIR >Oversizing considerd is 1.11X as against 1.14X considered for Projects in FY25-26 >Forex as on 30-May-2025: 85.7; Forex as on 04-Nov-25: 88.64 (assumption: further 1.5% depreciation considered by the time of balance payments) > Forex rate of 91.29 considered for PSS-12Capex estimates
A8: 2 | B8: PCS (2 Hour system) | C8: 110.9897 | D8: 0.1129779 | E8: 5.6488949 | F8: 5.1208601 | G8: 6.0739111 | H8: Total 384 Nos of PCS >Basic Cost USD 32,000/Number > Logistics Cost: USD 240/Number > BCD Cost @ 8.25% >Forex as on 30-May-2025: 85.7; Forex as on 04-Nov-25: 88.64 (assumption: further 1.5% depreciation considered by the time of balance payments) > Forex rate of 91.29 considered for PSS-11 Capex estimates
A9: 3 | B9: EMS (2 Hour system) | C9: 19.695183 | D9: 0.02004799 | E9: 1.0023995 | F9: 0.90869943 | G9: 1.0778188 | H9: > EMS: USD 1.25/kWh > Cost of Battery Operating Servers, Data Twin-Edge servers and Servers for Arbitrage Analytics considered
A10: 3.1 | B10: Battery + PCS + EMS | C10: 1669.354 | D10: 1.6992577 | E10: 84.962885 | F10: 77.020913 | G10: 91.355391 | H10: > 69.7 Lac / MWh
A11: 4 | B11: Transformer & NIFPS | C11: 86.269844 | D11: 0.087815225 | E11: 4.3907613 | F11: 3.9803314 | G11: 4.7211169 | H11: > Trafo (18/20MVA ONAN/ONAF) 48 Nos. @ Rs. 2.02 Cr/Nos. > Additional 1 Nos Trafo considered in Spare cost (Refer Sr. No. 8)
A12: 5 | B12: BOS Elec | C12: 125.85017 | D12: 0.12810457 | E12: 6.4052285 | F12: 5.8064948 | G12: 6.8871503 | H12: >7.27 Lac/MWh
A13: 5.1 | B13: HT Panel | C13: 13.064 | D13: 0.01329802 | E13: 0.664901 | F13: 0.60274886 | G13: 0.71492736 | H13: > 0.75 Lac/MWh >Increase in cost since one spare feeder considered in each panel to cater to future augmentation/ re-powering
A14: 5.2 | B14: DC LT Cable | C14: 52.85121 | D14: 0.053797952 | E14: 2.6898976 | F14: 2.4384573 | G14: 2.8922823 | H14: >3.05 Lac/MWh >Increase in cost since Armoured & watertight cables are being considered.
A15: 5.3 | B15: HT Cable | C15: 15.960389 | D15: 0.016246293 | E15: 0.81231466 | F15: 0.73638291 | G15: 0.87343225 | H15: >0.92 Lac/MWh >HT Cable length has increased in view of 3 land parcels and increased price of HT Cables
A16: 5.4 | B16: Scada Cable & FO | C16: 2.3869572 | D16: 0.0024297156 | E16: 0.12148578 | F16: 0.1101298 | G16: 0.13062623 | H16: >0.14 Lac/MWh > As per updated BoQ, spread over 2 land parcels
A17: 5.5 | B17: ACDC/ Electrical Erection | C17: 41.587616 | D17: 0.042332589 | E17: 2.1166294 | F17: 1.9187759 | G17: 2.2758821 | H17: >2.40 Lac/MWh > Price reduction is on account of descoping of below items: a. LT Panels: Rs 5.3 Cr b. Cable Tray: Rs 1.4 Cr > Price increase on account of higher Rating of CSS (3.15 MVA as against 2.5 MVA presently used) > Cost of High Masts included
A18: 6 | B18: Installation and Comissioning | C18: 16.284051 | D18: 0.016575752 | E18: 0.82878762 | F18: 0.75131605 | G18: 0.89114461 | H18: >0.94 Lac/Mwh > he weighted average for Installation and Commissioning activities for Projects of FY 2025-26 is 2.3 USD per KWh [2.5 USD for PSS 5, 10 and 1,5 USD for PSS 8]. For PSS 11, we have considered 0.66 USD per KWh > Rs 5.1 Cr considerd as hiring cost of 3 nos. 160/180 T Crane for handling Battery Containers.
A19: 7 | B19: BOP Civil | C19: 60.105884 | D19: 0.061182582 | E19: 3.0591291 | F19: 2.7731746 | G19: 3.2892943 | H19: > 3.47 Lac/MWh > Foundations of all structures considerd on DCIS Piling basis.
A20: 7.1 | B20: Battery container Precast | C20: 23.830014 | D20: 0.02425689 | E20: 1.2128445 | F20: 1.0994729 | G20: 1.3040975
A21: 7.2 | B21: Transformer (Precast) | C21: 7.7443241 | D21: 0.0078830508 | E21: 0.39415254 | F21: 0.35730883 | G21: 0.42380811
A22: 7.3 | B22: BOT (Precast) | C22: 0.8805624 | D22: 0.00089633622 | E22: 0.044816811 | F22: 0.040627525 | G22: 0.048188775
A23: 7.4 | B23: Nifps (Precast) | C23: 0.19225776 | D23: 0.00019570174 | E23: 0.009785087 | F23: 0.0088704184 | G23: 0.010521305
A24: 7.5 | B24: Cable rack support (Precast) | C24: 0.60669 | D24: 0.00061755785 | E24: 0.030877892 | F24: 0.027991557 | G24: 0.033201108
A25: 7.6 | B25: PCS & Panel Foundation | C25: 18.745555 | D25: 0.019081351 | E25: 0.95406754 | F25: 0.86488534 | G25: 1.0258504
A26: 7.7 | B26: CSS FOUNDATION | C26: 1.08706 | D26: 0.0011065329 | E26: 0.055326644 | F26: 0.050154943 | G26: 0.059489355
A27: 7.8 | B27: Control Room | C27: 1.5325312 | D27: 0.001559984 | E27: 0.077999198 | F27: 0.070708162 | G27: 0.083867765
A28: 7.9 | B28: SGR Panel | C28: 1.5020532 | D28: 0.00152896 | E28: 0.076448 | F28: 0.069301964 | G28: 0.082199857
A29: 7.10 | B29: Earthen Drain | C29: 0.238446 | D29: 0.00024271737 | E29: 0.012135868 | F29: 0.011001459 | G29: 0.013048957
A30: 7.11 | B30: Security container | C30: 0.32721 | D30: 0.00033307143 | E30: 0.016653571 | F30: 0.015096866 | G30: 0.017906566
A31: 7.12 | B31: Bund | C31: 0.217111 | D31: 0.00022100018 | E31: 0.011050009 | F31: 0.010017101 | G31: 0.011881399
A32: 7.13 | B32: Road & Drain | C32: 2.155923 | D32: 0.0021945428
A34: 7.14 | B34: Fencing | C34: 1.046146 | D34: 0.0010648859 | E34: 0.053244297 | F34: 0.048267245 | G34: 0.057250335
A35: 8 | B35: Spares | C35: 13.430602 | D35: 0.013671189 | E35: 0.68355947 | F35: 0.61966321 | G35: 0.73498967 | H35: >0.78 Lac/MWh > Includes OEM recommended Spares of BESS, PCS, EMS and other equipment > Complete set as a spare being ordered : Battery Container - 1, PCS - 4, Trafo - 1 and CSS - 2. > In addition, Tools and Tackles + 1 Reach Stacker considered
A36: 9 | B36: Consultancy Charges | C36: 2.72 | D36: 0.0027687243 | E36: 0.13843621 | F36: 0.12549578 | G36: 0.14885199 | H36: >0.16 Lac/MWh >Engineering Consultancy, Grid Study Consultancy, Consultancy for PIR
A37: 10 | B37: ISA | C37: 184.52849 | D37: 0.18783401 | E37: 9.3917007 | F37: 8.5138042 | G37: 10.098321 | H37: PSS-11 (SRPL Park Land Area): > Khavda RE Park ESIA charges (@19 lakhs/MW) > Khavda RE Park ISA charges (@0.07 lakh/MW) > Connectivity at 950 MW Lease charges (annual) for PSS 12 Till 31st July 2026 - Rs 19250 + GST (per hectare) After 1st Aug 2026 - Rs 21837 + GST (per hectare) Total Area considered for PSS12: 62.61 Acres or 25.34 Hectare
A38: 11 | B38: Taxes & Duties | C38: 388.53774 | D38: 0.39549775 | E38: 19.774888 | F38: 17.926415 | G38: 21.262727 | H38: > 18% GST on Sr. No. 1 to 10
A39: A. Total Hard Cost | C39: 2547.0808 | D39: 2.5927075 | E39: 129.63538 | F39: 117.51761 | G39: 139.38899 | H39: > 116.1 Lacs/ Mwh
A40: 12 | B40: Pre Ops | C40: 44.889455 | D40: 0.045693575 | E40: 2.2846788 | F40: 2.0711167 | G40: 2.4565753 | H40: Preops: Rs.2.54 Lakh/MWh
A41: 12.1 | B41: Pre Ops | C41: 10.375683 | D41: 0.010561546 | E41: 0.5280773 | F41: 0.47871487 | G41: 0.56780921
...

Sheet PSS 10_CAPEX
A1: PSS-10: 600 MW/ 1204 MWH (Installed DC)/ 1073 MWH (Dispatchable AC)
A3: Sr No | B3: TPC (Total Proposed Cost) | C3: Details Included in TPC | D3: Responsible Team | E3: Proposed Capex Cost for PSS-10 | K3: Remarks (All costs provided below are on basis of MWH dispatchable AC)
E4: DC Installed MW | F4: DC Installed Cr/MW | G4: DC Dispatchable MW | H4: AC Dispatachble MWH | I4: DC Installed MWH | J4: AC Dispatachble MWH
E5: 600 | F5: 600 | G5: 536.515 | H5: 1073.03 | I5: 1203.84 | J5: 1073.03
E6: (INR-Cr) Individual Basic Value | F6: (INR-Cr) Individual Basic Value | G6: INR Cr/ MW | H6: Rs. Lacs/ MWH | I6: Rs. Lacs/ MWH | J6: USD/kWh
A7: 1 | B7: Battery Containers (2 Hour system) | E7: 823.47469 | F7: 1.3724578 | G7: 1.5348587 | H7: 76.742933 | I7: 68.403998 | J7: 82.51698 | K7: Total Capacity 1204 MWh / 240 Nos of Containers > Basic Cost USD 55/KWh (Present regulation of 9% Export VAT refund in China to BESS OEMs is expected to be withdrawn from 01-Jan-2026. This could result in corresponding increase in BESS prices). > Logistics Cost: USD 0.95/kWh > BCD Cost @ 8.25% as per PIR >>Oversizing considerd is 1.11X as against 1.14X considered for Projects in FY25-26 >Forex as on 30-May-2025: 85.7; Forex as on 04-Nov-25: 88.64 (assumption: further 1.5% depreciation considered by the time of balance payments) > Forex rate of 91.29 considered for PSS-11 Capex estimates
A8: 2 | B8: PCS (2 Hour system) | C8: Logistics Order Currency Mandatorty spares BCD & Fwd rate | D8: TC team | E8: 69.368563 | F8: 0.11561427 | G8: 0.12929473 | H8: 6.4647366 | I8: 5.7622743 | J8: 6.9511358 | K8: Total 240 Nos of PCS >Basic Cost USD 32,000/Number > Logistics Cost: USD 240/Number > BCD Cost @ 8.25% >Forex as on 30-May-2025: 85.7; Forex as on 04-Nov-25: 88.64 (assumption: further 1.5% depreciation considered by the time of balance payments) > Forex rate of 91.29 considered for PSS-11 Capex estimates
A9: 3 | B9: EMS (2 Hour system) | C9: Mandatorty spares Logic/ Arcitecture scope FIT/FAT Requirement | D9: TC team/ Technology Team | E9: 12.30949 | F9: 0.020515816 | G9: 0.022943421 | H9: 1.1471711 | I9: 1.0225187 | J9: 1.2334829 | K9: > EMS: USD 1.25/kWh > Cost of Battery Operating Servers, Data Twin-Edge servers and Servers for Arbitrage Analytics considered
A10: 3.1 | B10: Battery + PCS + EMS | E10: 905.15274 | F10: 1.5085879 | G10: 1.6870968 | H10: 84.354841 | I10: 75.188791 | J10: 90.701599 | K10: >69.7 Lac/MWh
A11: 4 | B11: Transformer & NIFPS | C11: Capacity Nos. Initial estimates Type test charges if required | D11: Engg/TC Team | E11: 54.068652 | F11: 0.090114421 | G11: 0.10077752 | H11: 5.0388761 | I11: 4.4913487 | J11: 5.4179952 | K11: > Trafo (18/20MVA ONAN/ONAF) 30 Nos. @ Rs. 2.02 Cr/Nos.
A12: 5 | B12: BOS Elec | C12: Basic Layout and Cable lengths from Engg to get initial estimates from TC team | E12: 87.745251 | F12: 0.14624208 | G12: 0.16354669 | H12: 8.1773344 | I12: 7.2887801 | J12: 8.7925873 | K12: >8.14 Lac/MWH
A13: 5.1 | B13: HT Panel | C13: Nos and Capacity ABT & CT meter requirements | E13: 8.165 | F13: 0.013608333 | G13: 0.015218587 | H13: 0.76092933 | I13: 0.67824628 | J13: 0.81818075 | K13: > 0.76 Lac/MWh >Increase in cost since one spare feeder considered in each panel to cater to future augmentation/ re-powering
A14: 5.2 | B14: DC LT Cable | C14: Length & type | E14: 33.13593 | F14: 0.055226549 | G14: 0.061761423 | H14: 3.0880711 | I14: 2.7525194 | J14: 3.320414 | K14: >3.06 Lac/MWh >Increase in cost since Armoured & watertight cables are being considered.
A15: 5.3 | B15: HT Cable | C15: Length & type | E15: 15.960389 | F15: 0.026600649 | G15: 0.029748263 | H15: 1.4874131 | I15: 1.3257899 | J15: 1.5993243 | K15: >1.48 Lac/MWh
A16: 5.4 | B16: Scada Cable & FO | C16: Length & type | E16: 2.3271924 | F16: 0.003878654 | G16: 0.0043376092 | H16: 0.21688046 | I16: 0.19331409 | J16: 0.23319829 | K16: >0.22 Lac/MWh
A17: 5.5 | B17: ACDC/ Electrical Erection | C17: BoQ and Components considerations from Engg. | E17: 28.156739 | F17: 0.046927899 | G17: 0.052480806 | H17: 2.6240403 | I17: 2.3389104 | J17: 2.82147 | K17: >2.61 Lac/MWh > Price reduction is on account of descoping of below items: a. LT Panels: Rs 5.3 Cr b. Cable Tray: Rs 1.4 Cr > Price increase on account of higher Rating of CSS (3.15 MVA as against 2.5 MVA presently used) > Cost of High Masts included
A18: 6 | B18: Installation and Comissioning | C18: Based on FY 25-26 Requirements the estimates to be made | E18: 9.953431 | F18: 0.016589052 | G18: 0.018552009 | H18: 0.92760044 | I18: 0.8268068 | J18: 0.997392 | K18: >0.92 Lac/Mwh > Rs2.26 Cr considerd for hiring cost of 3 nos. 160/180 T Crane for handling Battery Containers.
A19: 7 | B19: BOP Civil | E19: 37.803917 | F19: 0.063006529 | G19: 0.070461996 | H19: 3.5230998 | I19: 3.1402776 | J19: 3.7881736 | K19: > 3.51 Lac/MWh > Foundations of all structures considerd on DCIS Piling basis.
A20: 7.1 | B20: Battery container | E20: 14.824332 | H20: 1.3815394 | I20: 1.2314205 | J20: 1.4854848
A21: 7.2 | B21: Transformer | E21: 4.8402025 | H21: 0.45107803 | I21: 0.40206361 | J21: 0.4850166
A22: 7.3 | B22: BOT | E22: 0.5503515 | H22: 0.051289479 | I22: 0.045716333 | J22: 0.055148439
A23: 7.4 | B23: Aux. Trafo | E23: 0.6794125 | H23: 0.063317195 | I23: 0.05643711 | J23: 0.068081106
A24: 7.5 | B24: Nifps | E24: 0.1201611 | H24: 0.011198298 | I24: 0.0099814843 | J24: 0.012040845
A25: 7.6 | B25: Cable rack support | E25: 0.3314325 | H25: 0.030887534 | I25: 0.027531275 | J25: 0.033211475
A26: 7.7 | B26: PCS & Panel Foundation | E26: 11.737347 | H26: 1.0938508 | I26: 0.97499227 | J26: 1.1761508
A27: 7.8 | B27: Control Room | E27: 0.978466 | H27: 0.091187199 | I27: 0.081278741 | J27: 0.098048016
A28: 7.9 | B28: SGR Panel | E28: 1.0651233 | H28: 0.099263138 | I28: 0.088477144 | J28: 0.10673158
A29: 7.10 | B29: Earthen Drain | E29: 0.14902875 | H29: 0.013888591 | I29: 0.012379448 | J29: 0.014933552
A30: 7.11 | B30: Security Container | E30: 0.163605 | H30: 0.015247011 | I30: 0.013590261 | J30: 0.016394178
A31: 7.12 | B31: Bund | E31: 0.2414025 | H31: 0.022497274 | I31: 0.020052706 | J31: 0.024189942
A32: 7.13 | B32: Road Works | E32: 1.3474519 | H32: 0.12557448 | I32: 0.11192948 | J32: 0.13502256
A34: 7.14 | B34: Fencing Works | E34: 0.77560087 | H34: 0.072281379 | I34: 0.064427239 | J34: 0.077719744
A35: 8 | B35: Spares | C35: Trafo CSS Cables ACDC Battery PCS EMS | E35: 5.5942534 | F35: 0.0093237557 | G35: 0.010427022 | H35: 0.52135108 | I35: 0.46470074 | J35: 0.56057691 | K35: >0.52 Lac/MWh > Includes OEM recommended Spares of BESS, PCS, EMS and other equipment > 1 spare Battery container, 4 PCS considered. > Tools and Tackles + 1 Reach Stacker considered
A36: 9 | B36: Consultancy Charges | E36: 2.72 | F36: 0.0045333333 | G36: 0.0050697558 | H36: 0.25348779 | I36: 0.22594365 | J36: 0.27255991 | K36: >0.25 Lac/MWh >Engineering Consultancy, Grid Study Consultancy, Consultancy for PIR
A37: 10 | B37: ISA | C37: ISA Contract and Per MW Value | D37: BD | E37: 115.84337 | F37: 0.19307229 | G37: 0.21591824 | H37: 10.795912 | I37: 9.6228213 | J37: 11.608183 | K37: PSS-10 (SRPL Park Land Area): > Khavda RE Park ESIA charges (@19 lakhs/MW) > Khavda RE Park ISA charges (@0.07 lakh/MW) > Connectivity at 600 MW Lease charges for PSS 10: Till 31st July 2026 - Rs 19250 + GST (per hectare) After 1st Aug 2026 - Rs 21837 + GST (per hectare) Total Area considered for PSS10: 39.04 Acres or15.8 Hectare
A38: 11 | B38: Taxes & Duties | E38: 219.39869 | F38: 0.36566449 | G38: 0.40893301 | H38: 20.44665 | I38: 18.224905 | J38: 21.985032 | K38: > 18% GST on Sr. No. 1 to 10
A39: A. Total Hard Cost | E39: 1438.2803 | F39: 2.3971339 | G39: 2.680783 | H39: 134.03915 | I39: 119.47437 | J39: 144.1241 | K39: > 117.47 Lacs/ Mwh
A40: 12 | B40: Pre Ops | D40: Site Wise/ Projects Wise requirements of below: | E40: 27.915118 | F40: 0.046525197 | G40: 0.052030453 | H40: 2.6015227 | I40: 2.3188396 | J40: 2.7972581 | K40: Preops: Rs.2.64 Lakh/MWh.
A41: 12.1 | B41: Pre Ops | E41: 6.1812676 | G41: 0.011521146 | H41: 0.5760573 | I41: 0.51346255 | J41: 0.61939917
A42: 12.2 | B42: Salary (including Corporate Charge) | E42: 18.96 | G42: 0.03533918 | H42: 1.766959 | I42: 1.5749601 | J42: 1.8999029
...

Sheet SAP Working
D1: Sr No | E1: Level | F1: Description | G1: AGEL | H1: AGE6L | I1: SPV
B2: Project Name | C2: SPV | D2: 1 | E2: 0 | F2: AGE27BL-Khavda-BESS-PSS-11- 1080 MW/ 2167 MWH | G2: H-5XA1 | H2: H-63A1 | I2: H-6074 | K2: Over All | Q2: AGEL | W2: AG6L | AC2: SPV
B3: Khavda- PSS 11 | C3: AGE27BL | D3: 2 | E3: 1 | F3: AGE27BL-Khavda-BESS-PSS-11- 1080 MW/ 2167 MWH | G3: H-5XA1 | H3: H-63A1 | I3: H-6074 | K3: Total SAP Budget | L3: Total Actual | M3: Total Commitement | N3: Total Assigned | O3: Total Available | Q3: SAP Budget | R3: Actual | S3: Commitement | T3: Assigned | U3: Available | W3: SAP Budget | X3: Actual | Y3: Commitement | Z3: Assigned | AA3: Available | AC3: SAP Budget | AD3: Actual | AE3: Commitement | AF3: Assigned | AG3: Available
A4: 1 | B4: Khavda- PSS 11 | C4: AGE27BL | D4: 3 | E4: 2 | F4: BESS Package | G4: H-5XA1-01 | H4: H-63A1-01 | I4: H-6074-01 | J4: H-5XA1* | K4: =Q4 -> 15424113969 | L4: =R4 -> 24214800 | M4: =S4 -> 1.2809909e+09 | N4: =M4+L4 -> 1.3052057e+09 | O4: =K4-N4 -> 1.4118908e+10 | Q4: =SUM(Q5:Q7) -> 15424113969 | R4: =SUM(R5:R7) -> 24214800 | S4: =SUM(S5:S7) -> 1.2809909e+09 | T4: =SUM(T5:T7) -> 1.3052057e+09 | U4: =SUM(U5:U7) -> 1.4118908e+10 | W4: =SUM(W5:W7) -> 0 | X4: =SUM(X5:X7) -> 0 | Y4: =SUM(Y5:Y7) -> 0 | Z4: =SUM(Z5:Z7) -> 0 | AA4: =SUM(AA5:AA7) -> 0 | AC4: =SUM(AC5:AC7) -> 17946171840 | AD4: =SUM(AD5:AD7) -> 6813600 | AE4: =SUM(AE5:AE7) -> 1.0597288e+10 | AF4: =SUM(AF5:AF7) -> 1.0604102e+10 | AG4: =SUM(AG5:AG7) -> 7.3420698e+09
B5: Khavda- PSS 11 | C5: AGE27BL | D5: 4 | E5: 3 | F5: BESS Containers | G5: H-5XA1-01-01 | H5: H-63A1-01-01 | I5: H-6074-01-01 | J5: H-63A1* | K5: =Q5 -> 15422501597 | L5: =R5 -> 24214800 | M5: =S5 -> 5.7153173e+08 | N5: =M5+L5 -> 5.9574653e+08 | O5: =K5-N5 -> 1.4826755e+10 | Q5: =SUMIF(Budgeted_01jun!U:U,'SAP Working'!G5,Budgeted_01jun!R:R) -> 15422501597 | R5: =SUMIF('Actual_30 jun'!I:I,'SAP Working'!G5,'Actual_30 jun'!K:K) -> 24214800 | S5: =SUMIF('Commited_30 Jun'!H:H,'SAP Working'!G5,'Commited_30 Jun'!I:I) -> 5.7153173e+08 | T5: =S5+R5 -> 5.9574653e+08 | U5: =Q5-T5 -> 1.4826755e+10 | W5: =SUMIF(Budgeted_01jun!$U:$U,H5,Budgeted_01jun!$R:$R) -> 0 | X5: =SUMIF('Actual_30 jun'!$I:$I,'SAP Working'!H5,'Actual_30 jun'!$K:$K) -> 0 | Y5: =SUMIF('Commited_30 Jun'!$H:$H,'SAP Working'!H5,'Commited_30 Jun'!$I:$I) -> 0 | Z5: =Y5+X5 -> 0 | AA5: =W5-Z5 -> 0 | AC5: =SUMIF(Budgeted_01jun!$U:$U,'SAP Working'!I5,Budgeted_01jun!$R:$R) -> 17946171840 | AD5: =SUMIF('Actual_30 jun'!$I:$I,'SAP Working'!I5,'Actual_30 jun'!$K:$K) -> 6813600 | AE5: =SUMIF('Commited_30 Jun'!$H:$H,'SAP Working'!I5,'Commited_30 Jun'!$I:$I) -> 1.0597288e+10 | AF5: =AE5+AD5 -> 1.0604102e+10 | AG5: =AC5-AF5 -> 7.3420698e+09
B6: Khavda- PSS 11 | C6: AGE27BL | D6: 5 | E6: 3 | F6: BESS CNT. Logistics | G6: H-5XA1-01-02 | H6: H-63A1-01-02 | I6: H-6074-01-02 | J6: H-6074* | K6: =Q6 -> 1612372 | L6: =R6 -> 0 | M6: =S6 -> 7.0945918e+08 | N6: =M6+L6 -> 7.0945918e+08 | O6: =K6-N6 -> -7.0784681e+08 | Q6: =SUMIF(Budgeted_01jun!U:U,'SAP Working'!G6,Budgeted_01jun!R:R) -> 1612372 | S6: =SUMIF('Commited_30 Jun'!H:H,'SAP Working'!G6,'Commited_30 Jun'!I:I) -> 7.0945918e+08 | T6: =S6+R6 -> 7.0945918e+08 | U6: =Q6-T6 -> -7.0784681e+08 | W6: =SUMIF(Budgeted_01jun!$U:$U,H6,Budgeted_01jun!$R:$R) -> 0 | X6: =SUMIF('Actual_30 jun'!$I:$I,'SAP Working'!H6,'Actual_30 jun'!$K:$K) -> 0 | Y6: =SUMIF('Commited_30 Jun'!$H:$H,'SAP Working'!H6,'Commited_30 Jun'!$I:$I) -> 0 | Z6: =Y6+X6 -> 0 | AA6: =W6-Z6 -> 0 | AC6: =SUMIF(Budgeted_01jun!$U:$U,'SAP Working'!I6,Budgeted_01jun!$R:$R) -> 0 | AD6: =SUMIF('Actual_30 jun'!$I:$I,'SAP Working'!I6,'Actual_30 jun'!$K:$K) -> 0 | AE6: =SUMIF('Commited_30 Jun'!$H:$H,'SAP Working'!I6,'Commited_30 Jun'!$I:$I) -> 0 | AF6: =AE6+AD6 -> 0 | AG6: =AC6-AF6 -> 0
B7: Khavda- PSS 11 | C7: AGE27BL | D7: 6 | E7: 3 | F7: Commissioning Support | G7: H-5XA1-01-03 | H7: H-63A1-01-03 | I7: H-6074-01-03 | J7: H-5XA2* | N7: =M7+L7 -> 0 | O7: =K7-N7 -> 0 | Q7: =SUMIF(Budgeted_01jun!U:U,'SAP Working'!G7,Budgeted_01jun!R:R) -> 0 | R7: =SUMIF('Actual_30 jun'!I:I,'SAP Working'!G7,'Actual_30 jun'!K:K) -> 0 | S7: =SUMIF('Commited_30 Jun'!H:H,'SAP Working'!G7,'Commited_30 Jun'!I:I) -> 0 | T7: =S7+R7 -> 0 | U7: =Q7-T7 -> 0 | W7: =SUMIF(Budgeted_01jun!$U:$U,H7,Budgeted_01jun!$R:$R) -> 0 | X7: =SUMIF('Actual_30 jun'!$I:$I,'SAP Working'!H7,'Actual_30 jun'!$K:$K) -> 0 | Y7: =SUMIF('Commited_30 Jun'!$H:$H,'SAP Working'!H7,'Commited_30 Jun'!$I:$I) -> 0 | Z7: =Y7+X7 -> 0 | AA7: =W7-Z7 -> 0 | AC7: =SUMIF(Budgeted_01jun!$U:$U,'SAP Working'!I7,Budgeted_01jun!$R:$R) -> 0 | AD7: =SUMIF('Actual_30 jun'!$I:$I,'SAP Working'!I7,'Actual_30 jun'!$K:$K) -> 0 | AE7: =SUMIF('Commited_30 Jun'!$H:$H,'SAP Working'!I7,'Commited_30 Jun'!$I:$I) -> 0 | AF7: =AE7+AD7 -> 0 | AG7: =AC7-AF7 -> 0
A8: 2 | B8: Khavda- PSS 11 | C8: AGE27BL | D8: =D7+1 -> 7 | E8: 2 | F8: PCS Package | G8: H-5XA1-02 | H8: H-63A1-02 | I8: H-6074-02 | J8: H-63A2* | K8: =Q8 -> 1.108616e+09 | L8: =R8 -> 3688830 | M8: =S8 -> 3.3168662e+09 | N8: =M8+L8 -> 3.320555e+09 | O8: =K8-N8 -> -2.2119391e+09 | Q8: =SUM(Q9:Q10) -> 1.108616e+09 | R8: =SUM(R9:R10) -> 3688830 | S8: =SUM(S9:S10) -> 3.3168662e+09 | T8: =SUM(T9:T10) -> 3.320555e+09 | U8: =SUM(U9:U10) -> -2.2119391e+09 | W8: =SUM(W9:W10) -> 0 | X8: =SUMIF('Actual_30 jun'!$I:$I,'SAP Working'!H8,'Actual_30 jun'!$K:$K) -> 0 | Y8: =SUMIF('Commited_30 Jun'!$H:$H,'SAP Working'!H8,'Commited_30 Jun'!$I:$I) -> 0 | Z8: =SUM(Z9:Z10) -> 0 | AA8: =SUM(AA9:AA10) -> 0 | AC8: =SUM(AC9:AC10) -> 1254575958 | AD8: =SUM(AD9:AD10) -> 0 | AE8: =SUM(AE9:AE10) -> 1.0092656e+09 | AF8: =SUM(AF9:AF10) -> 1.0092656e+09 | AG8: =SUM(AG9:AG10) -> 2.4531039e+08
B9: Khavda- PSS 11 | C9: AGE27BL | D9: =D8+1 -> 8 | E9: 3 | F9: PCS Supply | G9: H-5XA1-02-01 | H9: H-63A1-02-01 | I9: H-6074-02-01 | J9: H-6764* | K9: =Q9 -> 1.1070036e+09 | L9: =R9 -> 3688830 | M9: =S9 -> 5.6905399e+08 | N9: =M9+L9 -> 5.7274282e+08 | O9: =K9-N9 -> 5.3426077e+08 | Q9: =SUMIF(Budgeted_01jun!U:U,'SAP Working'!G9,Budgeted_01jun!R:R) -> 1.1070036e+09 | R9: =SUMIF('Actual_30 jun'!I:I,'SAP Working'!G9,'Actual_30 jun'!K:K) -> 3688830 | S9: =SUMIF('Commited_30 Jun'!H:H,'SAP Working'!G9,'Commited_30 Jun'!I:I) -> 5.6905399e+08 | T9: =S9+R9 -> 5.7274282e+08 | U9: =Q9-T9 -> 5.3426077e+08 | W9: =SUMIF(Budgeted_01jun!$U:$U,H9,Budgeted_01jun!$R:$R) -> 0 | X9: =SUMIF('Actual_30 jun'!$I:$I,'SAP Working'!H9,'Actual_30 jun'!$K:$K) -> 0 | Y9: =SUMIF('Commited_30 Jun'!$H:$H,'SAP Working'!H9,'Commited_30 Jun'!$I:$I) -> 0 | Z9: =Y9+X9 -> 0 | AA9: =W9-Z9 -> 0 | AC9: =SUMIF(Budgeted_01jun!$U:$U,'SAP Working'!I9,Budgeted_01jun!$R:$R) -> 1254575958 | AD9: =SUMIF('Actual_30 jun'!$I:$I,'SAP Working'!I9,'Actual_30 jun'!$K:$K) -> 0 | AE9: =SUMIF('Commited_30 Jun'!$H:$H,'SAP Working'!I9,'Commited_30 Jun'!$I:$I) -> 1.0092656e+09 | AF9: =AE9+AD9 -> 1.0092656e+09 | AG9: =AC9-AF9 -> 2.4531039e+08
B10: Khavda- PSS 11 | C10: AGE27BL | D10: =D9+1 -> 9 | E10: 3 | F10: PCS Cnt. Logistics | G10: H-5XA1-02-02 | H10: H-63A1-02-02 | I10: H-6074-02-02 | J10: H-51X9* | K10: =Q10 -> 1612372 | L10: =R10 -> 0 | M10: =S10 -> 2.7478122e+09 | N10: =M10+L10 -> 2.7478122e+09 | O10: =K10-N10 -> -2.7461998e+09 | Q10: =SUMIF(Budgeted_01jun!U:U,'SAP Working'!G10,Budgeted_01jun!R:R) -> 1612372 | R10: =SUMIF('Actual_30 jun'!I:I,'SAP Working'!G10,'Actual_30 jun'!K:K) -> 0 | S10: =SUMIF('Commited_30 Jun'!H:H,'SAP Working'!G10,'Commited_30 Jun'!I:I) -> 2.7478122e+09 | T10: =S10+R10 -> 2.7478122e+09 | U10: =Q10-T10 -> -2.7461998e+09 | W10: =SUMIF(Budgeted_01jun!$U:$U,H10,Budgeted_01jun!$R:$R) -> 0 | X10: =SUMIF('Actual_30 jun'!$I:$I,'SAP Working'!H10,'Actual_30 jun'!$K:$K) -> 0 | Y10: =SUMIF('Commited_30 Jun'!$H:$H,'SAP Working'!H10,'Commited_30 Jun'!$I:$I) -> 0 | Z10: =Y10+X10 -> 0 | AA10: =W10-Z10 -> 0 | AC10: =SUMIF(Budgeted_01jun!$U:$U,'SAP Working'!I10,Budgeted_01jun!$R:$R) -> 0 | AD10: =SUMIF('Actual_30 jun'!$I:$I,'SAP Working'!I10,'Actual_30 jun'!$K:$K) -> 0 | AE10: =SUMIF('Commited_30 Jun'!$H:$H,'SAP Working'!I10,'Commited_30 Jun'!$I:$I) -> 0 | AF10: =AE10+AD10 -> 0 | AG10: =AC10-AF10 -> 0
A11: 3 | B11: Khavda- PSS 11 | C11: AGE27BL | D11: =D10+1 -> 10 | E11: 2 | F11: EMS Package | G11: H-5XA1-03 | H11: H-63A1-03 | I11: H-6074-03 | J11: H-63X9* | K11: =Q11 -> 125000000 | L11: =R11 -> 2921790 | M11: =S11 -> 1.9780614e+08 | N11: =M11+L11 -> 2.0072793e+08 | O11: =K11-N11 -> -75727930 | Q11: =SUM(Q12:Q13) -> 125000000 | R11: =SUM(R12:R13) -> 2921790 | S11: =SUM(S12:S13) -> 1.9780614e+08 | T11: =SUM(T12:T13) -> 2.0072793e+08 | U11: =SUM(U12:U13) -> -75727930 | W11: =SUM(W12:W13) -> 0 | X11: =SUMIF('Actual_30 jun'!$I:$I,'SAP Working'!H11,'Actual_30 jun'!$K:$K) -> 0 | Y11: =SUMIF('Commited_30 Jun'!$H:$H,'SAP Working'!H11,'Commited_30 Jun'!$I:$I) -> 0 | Z11: =SUM(Z12:Z13) -> 0 | AA11: =SUM(AA12:AA13) -> 0 | AC11: =SUM(AC12:AC13) -> 0 | AD11: =SUM(AD12:AD13) -> 0 | AE11: =SUM(AE12:AE13) -> 0 | AF11: =SUM(AF12:AF13) -> 0 | AG11: =SUM(AG12:AG13) -> 0
B12: Khavda- PSS 11 | C12: AGE27BL | D12: =D11+1 -> 11 | E12: 3 | F12: EMS Supply | G12: H-5XA1-03-01 | H12: H-63A1-03-01 | I12: H-6074-03-01 | J12: H-51N2* | K12: =Q12 -> 125000000 | L12: =R12 -> 2921790 | M12: =S12 -> 1.9780614e+08 | N12: =M12+L12 -> 2.0072793e+08 | O12: =K12-N12 -> -75727930 | Q12: =SUMIF(Budgeted_01jun!U:U,'SAP Working'!G12,Budgeted_01jun!R:R) -> 125000000 | R12: =SUMIF('Actual_30 jun'!I:I,'SAP Working'!G12,'Actual_30 jun'!K:K) -> 2921790 | S12: =SUMIF('Commited_30 Jun'!H:H,'SAP Working'!G12,'Commited_30 Jun'!I:I) -> 1.9780614e+08 | T12: =S12+R12 -> 2.0072793e+08 | U12: =Q12-T12 -> -75727930 | W12: =SUMIF(Budgeted_01jun!$U:$U,H12,Budgeted_01jun!$R:$R) -> 0 | X12: =SUMIF('Actual_30 jun'!$I:$I,'SAP Working'!H12,'Actual_30 jun'!$K:$K) -> 0 | Y12: =SUMIF('Commited_30 Jun'!$H:$H,'SAP Working'!H12,'Commited_30 Jun'!$I:$I) -> 0 | Z12: =Y12+X12 -> 0 | AA12: =W12-Z12 -> 0 | AC12: =SUMIF(Budgeted_01jun!$U:$U,'SAP Working'!I12,Budgeted_01jun!$R:$R) -> 0 | AD12: =SUMIF('Actual_30 jun'!$I:$I,'SAP Working'!I12,'Actual_30 jun'!$K:$K) -> 0 | AE12: =SUMIF('Commited_30 Jun'!$H:$H,'SAP Working'!I12,'Commited_30 Jun'!$I:$I) -> 0 | AF12: =AE12+AD12 -> 0 | AG12: =AC12-AF12 -> 0
B13: Khavda- PSS 11 | C13: AGE27BL | D13: =D12+1 -> 12 | E13: 3 | F13: EMS Logistics | G13: H-5XA1-03-02 | H13: H-63A1-03-02 | I13: H-6074-03-02 | J13: H-5XWG* | K13: =Q13 -> 0 | L13: =R13 -> 0 | M13: =S13 -> 0 | N13: =M13+L13 -> 0 | O13: =K13-N13 -> 0 | Q13: =SUMIF(Budgeted_01jun!U:U,'SAP Working'!G13,Budgeted_01jun!R:R) -> 0 | R13: =SUMIF('Actual_30 jun'!I:I,'SAP Working'!G13,'Actual_30 jun'!K:K) -> 0 | S13: =SUMIF('Commited_30 Jun'!H:H,'SAP Working'!G13,'Commited_30 Jun'!I:I) -> 0 | T13: =S13+R13 -> 0 | U13: =Q13-T13 -> 0 | W13: =SUMIF(Budgeted_01jun!$U:$U,H13,Budgeted_01jun!$R:$R) -> 0 | X13: =SUMIF('Actual_30 jun'!$I:$I,'SAP Working'!H13,'Actual_30 jun'!$K:$K) -> 0 | Y13: =SUMIF('Commited_30 Jun'!$H:$H,'SAP Working'!H13,'Commited_30 Jun'!$I:$I) -> 0 | Z13: =Y13+X13 -> 0 | AA13: =W13-Z13 -> 0 | AC13: =SUMIF(Budgeted_01jun!$U:$U,'SAP Working'!I13,Budgeted_01jun!$R:$R) -> 0 | AD13: =SUMIF('Actual_30 jun'!$I:$I,'SAP Working'!I13,'Actual_30 jun'!$K:$K) -> 0 | AE13: =SUMIF('Commited_30 Jun'!$H:$H,'SAP Working'!I13,'Commited_30 Jun'!$I:$I) -> 0 | AF13: =AE13+AD13 -> 0 | AG13: =AC13-AF13 -> 0
A14: 4 | B14: Khavda- PSS 11 | C14: AGE27BL | D14: =D13+1 -> 13 | E14: 2 | F14: IDT Transformer Supply | G14: H-5XA1-04 | H14: H-63A1-04 | I14: H-6074-04 | J14: H-63WG* | K14: =Q14+W14 -> 979795453 | L14: =R14+X14 -> 163337700 | M14: =S14+Y14 -> 1.4057038e+09 | N14: =M14+L14 -> 1.5690415e+09 | O14: =K14-N14 -> -5.89246e+08 | Q14: =SUMIF(Budgeted_01jun!U:U,'SAP Working'!G14,Budgeted_01jun!R:R) -> 956571053 | R14: =SUMIF('Actual_30 jun'!I:I,'SAP Working'!G14,'Actual_30 jun'!K:K) -> 159804930 | S14: =SUMIF('Commited_30 Jun'!H:H,'SAP Working'!G14,'Commited_30 Jun'!I:I) -> 0 | T14: =S14+R14 -> 159804930 | U14: =Q14-T14 -> 796766123 | W14: =SUMIF(Budgeted_01jun!$U:$U,H14,Budgeted_01jun!$R:$R) -> 23224400 | X14: =SUMIF('Actual_30 jun'!$I:$I,'SAP Working'!H14,'Actual_30 jun'!$K:$K) -> 3532770 | Y14: =SUMIF('Commited_30 Jun'!$H:$H,'SAP Working'!H14,'Commited_30 Jun'!$I:$I) -> 1.4057038e+09 | Z14: =Y14+X14 -> 1.4092365e+09 | AA14: =W14-Z14 -> -1.3860121e+09 | AC14: =SUMIF(Budgeted_01jun!$U:$U,'SAP Working'!I14,Budgeted_01jun!$R:$R) -> 9.2907344e+08 | AD14: =SUMIF('Actual_30 jun'!$I:$I,'SAP Working'!I14,'Actual_30 jun'!$K:$K) -> 8570550 | AE14: =SUMIF('Commited_30 Jun'!$H:$H,'SAP Working'!I14,'Commited_30 Jun'!$I:$I) -> 0 | AF14: =AE14+AD14 -> 8570550 | AG14: =AC14-AF14 -> 9.2050289e+08
A15: 6 | B15: Khavda- PSS 11 | C15: AGE27BL | D15: =D14+1 -> 14 | E15: 2 | F15: Installation, Integration & Commissioning DC Side | G15: H-5XA1-05 | H15: H-63A1-05 | I15: H-6074-05 | J15: H-6497* | K15: =W15 -> 119657314 | L15: =X15 -> 0 | M15: =Y15 -> 3.0587684e+09 | N15: =M15+L15 -> 3.0587684e+09 | O15: =K15-N15 -> -2.9391111e+09 | Q15: =SUM(Q16:Q18) -> 0 | R15: =SUM(R16:R18) -> 0 | S15: =SUM(S16:S18) -> 0 | T15: =SUM(T16:T18) -> 0 | U15: =SUM(U16:U18) -> 0 | W15: =SUM(W16:W18) -> 119657314 | X15: =SUM(X16:X18) -> 0 | Y15: =SUM(Y16:Y18) -> 3.0587684e+09 | Z15: =SUM(Z16:Z18) -> 3.0587684e+09 | AA15: =SUM(AA16:AA18) -> -2.9391111e+09 | AC15: =SUM(AC16:AC18) -> 0 | AD15: =SUM(AD16:AD18) -> 0 | AE15: =SUM(AE16:AE18) -> 0 | AF15: =SUM(AF16:AF18) -> 0 | AG15: =SUM(AG16:AG18) -> 0
