Workbook
Name KAW1_EPC_SYD_DE_H_417: PSS05B!#REF!
Name KAW1_EPC_SYD_DE_H_417: PSS08B!#REF!
Name KAW1_EPC_SYD_DE_H_417: 'PSS09'!#REF!
Name KAW1_EPC_SYD_DE_H_417: PSS10B!#REF!
Name KAW1_EPC_SYD_DE_H_417: 'PSS11'!#REF!
Name KAW1_EPC_SYD_DE_H_417: 'PSS12'!#REF!
Name KAW1_EPC_SYD_DE_H_417: 'PSS8-old'!$F$163:$F$163
Name KAW1_EPC_SYD_DE_H_417: #REF!

Sheet MDL PSS Summery (2)
A1: STATUS AS ON DATE | H1: STATUS AS ON DATE | J1: 01.01.2025
A2: KHAVDA- BESS PSS MDL STATUS | H2: KHAVDA PSS MDL STATUS-PHASE-3 | O2: Approval Status
A3: 1 | B3: PSS-5 | F3: REMARKS | H3: 1 | I3: PSS-6 | M3: REMARKS | O3: RFC | P3: A1 | Q3: A2 | R3: A3 | S3: I | T3: UR | AF3: Date : | AG3: =TODAY() -> 46269
B4: CIVIL/ELECT COMBINED (PSS) | C4: Submitted | D4: =#REF! -> #REF! | E4: =D4/D6 -> #REF! | I4: CIVIL/ELECT COMBINED (PSS) | J4: Submitted | K4: =8+6 -> 14 | L4: =K4/K6 -> 0.56 | M4: Hyosung-19 added-offline submitted docu. | O4: =#REF! -> #REF! | P4: =#REF! -> #REF! | Q4: =#REF! -> #REF! | R4: =#REF! -> #REF! | S4: =#REF! -> #REF! | T4: =#REF! -> #REF! | V4: KHAVDA- BESS PSS MDL STATUS
C5: Not Submitted | D5: =#REF! -> #REF! | E5: =D5/D6 -> #REF! | J5: Not Submitted | K5: 11 | L5: =K5/K6 -> 0.44 | V5: Project | W5: Total Docment | Z5: Approval Status | AG5: Not Submitted
C6: Total | D6: =SUM(D4:D5) -> #REF! | J6: Total | K6: =SUM(K4:K5) -> 25 | W6: Total | X6: In-House | Y6: Vendor | Z6: Total | AA6: RFC | AB6: A1 | AC6: A2 | AD6: A3 | AE6: I | AF6: UR | AG6: Total | AH6: In-House | AI6: Vendor
A7: 2 | B7: PSS-8 | F7: REMARKS | H7: 2 | I7: PSS-7 | M7: REMARKS | O7: RFC | P7: A1 | Q7: A2 | R7: A3 | S7: I | T7: UR | V7: PSS-5 | W7: =SUM(X7,Y7) -> #REF! | X7: =COUNTIF(#REF!,'MDL PSS Summery (2)'!X6) -> #REF! | Y7: =COUNTIF(#REF!,'MDL PSS Summery (2)'!Y6) -> #REF! | Z7: =SUM(AA7:AF7) -> #REF! | AA7: =O4 -> #REF! | AB7: =P4 -> #REF! | AC7: =Q4 -> #REF! | AD7: =R4 -> #REF! | AE7: =S4 -> #REF! | AF7: =T4 -> #REF! | AG7: =SUM(AH7,AI7) -> #REF! | AH7: =COUNTIFS(#REF!,'MDL PSS Summery (2)'!AH6,#REF!,"Not Submitted") -> #REF! | AI7: =COUNTIFS(#REF!,'MDL PSS Summery (2)'!AI6,#REF!,"Not Submitted") -> #REF!
B8: CIVIL/ELECT COMBINED (PSS) | C8: Submitted | D8: =#REF! -> #REF! | E8: =D8/D10 -> #REF! | I8: CIVIL/ELECT COMBINED (PSS) | J8: Submitted | K8: 9 | L8: =K8/K10 -> 0.47368421 | M8: Hyosung-19 | O8: =#REF! -> #REF! | P8: =#REF! -> #REF! | Q8: =#REF! -> #REF! | R8: =#REF! -> #REF! | S8: =#REF! -> #REF! | T8: =#REF! -> #REF! | V8: PSS-8 | W8: =SUM(X8,Y8) -> #REF! | X8: =COUNTIF(#REF!,'MDL PSS Summery (2)'!X6) -> #REF! | Y8: =COUNTIF(#REF!,'MDL PSS Summery (2)'!Y6) -> #REF! | Z8: =SUM(AA8:AF8) -> #REF! | AA8: =O8 -> #REF! | AB8: =P8 -> #REF! | AC8: =Q8 -> #REF! | AD8: =R8 -> #REF! | AE8: =S8 -> #REF! | AF8: =T8 -> #REF! | AG8: =SUM(AH8,AI8) -> #REF! | AH8: =COUNTIFS(#REF!,'MDL PSS Summery (2)'!AH6,#REF!,"Not Submitted") -> #REF! | AI8: =COUNTIFS(#REF!,'MDL PSS Summery (2)'!AI6,#REF!,"Not Submitted") -> #REF!
C9: Not Submitted | D9: =#REF! -> #REF! | E9: =D9/D10 -> #REF! | J9: Not Submitted | K9: 10 | L9: =K9/K10 -> 0.52631579 | V9: PSS-10 | W9: =SUM(X9,Y9) -> 102 | X9: =COUNTIF(PSS10B!$D$3:$D$104,'MDL PSS Summery (2)'!X6) -> 0 | Y9: =COUNTIF(PSS10B!$D$3:$D$104,'MDL PSS Summery (2)'!Y6) -> 102 | Z9: =SUM(AA9:AF9) -> #REF! | AA9: =O12 -> #REF! | AB9: =P12 -> #REF! | AC9: =Q12 -> #REF! | AD9: =R12 -> #REF! | AE9: =S12 -> #REF! | AF9: =T12 -> #REF! | AG9: =SUM(AH9,AI9) -> 12 | AH9: =COUNTIFS(PSS10B!$D$3:$D$104,'MDL PSS Summery (2)'!AH6,PSS10B!$N$3:$N$104,"Not Submitted") -> 0 | AI9: =COUNTIFS(PSS10B!$D$3:$D$104,'MDL PSS Summery (2)'!AI6,PSS10B!$N$3:$N$104,"Not Submitted") -> 12
C10: Total | D10: =SUM(D8:D9) -> #REF! | J10: Total | K10: =SUM(K8:K9) -> 19 | V10: Total | W10: =SUM(W7:W9) -> #REF! | X10: =SUM(X7:X9) -> #REF! | Y10: =SUM(Y7:Y9) -> #REF! | Z10: =SUM(AA10:AF10) -> #REF! | AA10: =SUM(AA7:AA9) -> #REF! | AB10: =SUM(AB7:AB9) -> #REF! | AC10: =SUM(AC7:AC9) -> #REF! | AD10: =SUM(AD7:AD9) -> #REF! | AE10: =SUM(AE7:AE9) -> #REF! | AF10: =SUM(AF7:AF9) -> #REF! | AG10: =SUM(AG7:AG9) -> #REF! | AH10: =SUM(AH7:AH9) -> #REF! | AI10: =SUM(AI7:AI9) -> #REF!
A11: 3 | B11: PSS-10 | F11: REMARKS | H11: 3 | I11: PSS-11 | M11: REMARKS | O11: RFC | P11: A1 | Q11: A2 | R11: A3 | S11: I | T11: UR
B12: CIVIL/ELECT COMBINED (PSS) | C12: Submitted | D12: =PSS10B!#REF! -> #REF! | E12: =D12/D14 -> #REF! | I12: CIVIL/ELECT COMBINED (PSS) | J12: Submitted | K12: 8 | L12: =K12/K14 -> 0.42105263 | M12: Hyosung-19 | O12: =PSS10B!#REF! -> #REF! | P12: =PSS10B!#REF! -> #REF! | Q12: =PSS10B!#REF! -> #REF! | R12: =PSS10B!#REF! -> #REF! | S12: =PSS10B!#REF! -> #REF! | T12: =PSS10B!#REF! -> #REF!
C13: Not Submitted | D13: =PSS10B!#REF! -> #REF! | E13: =D13/D14 -> #REF! | J13: Not Submitted | K13: 11 | L13: =K13/K14 -> 0.57894737
C14: Total | D14: =SUM(D12:D13) -> #REF! | J14: Total | K14: =SUM(K12:K13) -> 19
B16: Grand Total | F16: REMARKS | I16: Grand Total | M16: REMARKS
B17: CIVIL/ELECT COMBINED (PSS) | C17: Submitted | D17: =SUM(D4,D8,D12) -> #REF! | E17: =D17/D19 -> #REF! | I17: CIVIL/ELECT COMBINED (PSS) | J17: Submitted | K17: =SUM(K4,K8,K12,#REF!,#REF!) -> #REF! | L17: =K17/K19 -> #REF!
C18: Not Submitted | D18: =SUM(D5,D9,D13) -> #REF! | E18: =D18/D19 -> #REF! | J18: Not Submitted | K18: =SUM(K5,K9,K13,#REF!,#REF!) -> #REF! | L18: =K18/K19 -> #REF!
C19: Total | D19: =SUM(D17:D18) -> #REF! | J19: Total | K19: =SUM(K17:K18) -> #REF!

Sheet PSS09
A1: PSS09_Adani Green Energy 27 A Limited (AGE27AL) | O1: Rev.00 | T1: Rev.01 | Y1: Rev.02 | AD1: Rev.03 | AI1: Rev.04/0E | AN1: Rev.05/0F | AS1: Rev.06/0G | AX1: Rev.07/0H | BC1: Rev.08/0I | BH1: Rev.09/0J
A2: Sr. No. | B2: Project | C2: Package | D2: In-house/Vendor | E2: In-house/Vendor Name2 | F2: New_Drawing / Document Number | G2: Drawing / Document Number | H2: Document Title | I2: Document Category | J2: DOCUMENT TYPE | K2: Schedule Date | L2: FORECAST DATE | M2: Weightage | N2: Status | O2: Recd Date_00 | P2: Comment date_00 | Q2: Status_00 | R2: XMTL No._00 | S2: Remarks_00 | T2: Recd Date_01 | U2: Comment date_01 | V2: Status_01 | W2: XMTL No._01 | X2: Remarks_01 | Y2: Recd Date_02 | Z2: Comment date_02 | AA2: Status_02 | AB2: XMTL No._02 | AC2: Remarks_02 | AD2: Recd Date_03 | AE2: Comment date_03 | AF2: Status_03 | AG2: XMTL No._03 | AH2: Remarks_03 | AI2: Recd Date_04 | AJ2: Comment date_04 | AK2: Status_04 | AL2: XMTL No._04 | AM2: Remarks_04 | AN2: Recd Date_05 | AO2: Comment date_05 | AP2: Status_05 | AQ2: XMTL No._05 | AR2: Remarks_05 | AS2: Recd Date_06 | AT2: Comment date_06 | AU2: Status_06 | AV2: XMTL No._06 | AW2: Remarks_06 | AX2: Recd Date_07 | AY2: Comment date_07 | AZ2: Status_07 | BA2: XMTL No._07 | BB2: Remarks_07 | BC2: Recd Date_08 | BD2: Comment date_08 | BE2: Status_08 | BF2: XMTL No._08 | BG2: Remarks_08 | BH2: Recd Date_09 | BI2: Comment date_09 | BJ2: Status_09 | BK2: XMTL No._09 | BL2: Remarks_09 | BM2: Remarks_10
A3: 1 | B3: =$A$1 -> PSS09_Adani Green Energy 27 A Limited (AGE27AL) | C3: Coupling Transformer | D3: Vendor | E3: Ornet | F3: 6497-ORNT-CTF-GEN-DE-V-0001 | G3: 51H2-E-SEP-IDT-DE-G-V-0001 | H3: GA Drawings with List of Fittings for IDT | I3: Approval | J3: Drawing | N3: {=_xlfn.IFNA(LOOKUP(2, 1/(MOD(COLUMN(O3:XFD3)-COLUMN(O3), 5)=2)/(O3:XFD3<>""), O3:XFD3),"Not Submitted")} -> Cat. -I | O3: 46063 | P3: 46079 | Q3: Cat. -I | R3: XXXX-BESS-SITE-T-0001 | BM3: =MID(F3,20,1) -> E
A4: 2 | B4: =$A$1 -> PSS09_Adani Green Energy 27 A Limited (AGE27AL) | C4: Coupling Transformer | D4: Vendor | E4: Ornet | F4: 6497-ORNT-CTF-GEN-DE-V-0002 | G4: 51H2-E-SEP-IDT-DE-G-V-0002 | H4: GA OF MARSHALLING BOX & WIRING DIAGRAM and SCHEMATIC DIAGRAM OF COOLING SYSTEM | I4: Approval | J4: Drawing | N4: {=_xlfn.IFNA(LOOKUP(2, 1/(MOD(COLUMN(O4:XFD4)-COLUMN(O4), 5)=2)/(O4:XFD4<>""), O4:XFD4),"Not Submitted")} -> Cat. -I | O4: 46063 | P4: 46079 | Q4: Cat. -I | R4: XXXX-BESS-SITE-T-0001 | BM4: =MID(F4,20,1) -> E
A5: 3 | B5: =$A$1 -> PSS09_Adani Green Energy 27 A Limited (AGE27AL) | C5: Coupling Transformer | D5: Vendor | E5: Ornet | F5: 6497-ORNT-CTF-GEN-DE-V-0003 | G5: 51H2-E-SEP-IDT-DE-G-V-0003 | H5: CTR NIFPS (Nitrogen Injection & Fire Protection System) Drawings | I5: Approval | J5: Drawing | N5: {=_xlfn.IFNA(LOOKUP(2, 1/(MOD(COLUMN(O5:XFD5)-COLUMN(O5), 5)=2)/(O5:XFD5<>""), O5:XFD5),"Not Submitted")} -> Delete | Q5: Delete | BM5: =MID(F5,20,1) -> E
A6: 4 | B6: =$A$1 -> PSS09_Adani Green Energy 27 A Limited (AGE27AL) | C6: Coupling Transformer | D6: Vendor | E6: Ornet | F6: 6497-ORNT-CTF-GEN-DE-V-0004 | G6: 51H2-E-SEP-IDT-DE-G-V-0004 | H6: ONLINE DRYING SYSTEM DRAWING WITH GUARANRTEED TECHNICAL PARTICULARS | I6: Approval | J6: Drawing | N6: {=_xlfn.IFNA(LOOKUP(2, 1/(MOD(COLUMN(O6:XFD6)-COLUMN(O6), 5)=2)/(O6:XFD6<>""), O6:XFD6),"Not Submitted")} -> Not Submitted | BM6: =MID(F6,20,1) -> E
A7: 5 | B7: =$A$1 -> PSS09_Adani Green Energy 27 A Limited (AGE27AL) | C7: Coupling Transformer | D7: Vendor | E7: Ornet | F7: 6497-ORNT-CTF-GEN-DE-V-0005 | G7: 51H2-E-SEP-IDT-DE-G-V-0005 | H7: EMR NIFPS (Nitrogen Injection & Fire Protection System) Drawings | I7: Approval | J7: Drawing | N7: {=_xlfn.IFNA(LOOKUP(2, 1/(MOD(COLUMN(O7:XFD7)-COLUMN(O7), 5)=2)/(O7:XFD7<>""), O7:XFD7),"Not Submitted")} -> Cat. -I | O7: 46063 | P7: 46079 | Q7: Cat. -I | R7: XXXX-BESS-SITE-T-0001 | BM7: =MID(F7,20,1) -> E
A8: 6 | B8: =$A$1 -> PSS09_Adani Green Energy 27 A Limited (AGE27AL) | C8: Coupling Transformer | D8: Vendor | E8: Ornet | F8: 6497-ORNT-CTF-GEN-DE-D-0001 | G8: 51H2-E-SEP-IDT-DE-D-V-0001 | H8: GTP of IDT | I8: Approval | J8: Document | N8: {=_xlfn.IFNA(LOOKUP(2, 1/(MOD(COLUMN(O8:XFD8)-COLUMN(O8), 5)=2)/(O8:XFD8<>""), O8:XFD8),"Not Submitted")} -> Cat. -I | O8: 46063 | P8: 46079 | Q8: Cat. -I | R8: XXXX-BESS-SITE-T-0001 | BM8: =MID(F8,20,1) -> E
A9: 7 | B9: =$A$1 -> PSS09_Adani Green Energy 27 A Limited (AGE27AL) | C9: Coupling Transformer | D9: Vendor | E9: Ornet | F9: 6497-ORNT-CTF-GEN-DE-M-0001 | G9: 51H2-E-SEP-IDT-DE-M-V-0001 | H9: O&M Manual of IDT | I9: Approval | J9: Document | N9: {=_xlfn.IFNA(LOOKUP(2, 1/(MOD(COLUMN(O9:XFD9)-COLUMN(O9), 5)=2)/(O9:XFD9<>""), O9:XFD9),"Not Submitted")} -> Not Submitted | BM9: =MID(F9,20,1) -> E
A10: 8 | B10: =$A$1 -> PSS09_Adani Green Energy 27 A Limited (AGE27AL) | C10: Coupling Transformer | D10: Vendor | E10: Tesla | F10: 6497-TESL-CTF-GEN-DE-V-0001 | G10: 51H2-E-SEP-IDT-DE-G-V-0001 | H10: GA Drawings with List of Fittings for IDT | I10: Approval | J10: Drawing | K10: 46185 | N10: {=_xlfn.IFNA(LOOKUP(2, 1/(MOD(COLUMN(O10:XFD10)-COLUMN(O10), 5)=2)/(O10:XFD10<>""), O10:XFD10),"Not Submitted")} -> Not Submitted | BM10: =MID(F10,20,1) -> E
A11: 9 | B11: =$A$1 -> PSS09_Adani Green Energy 27 A Limited (AGE27AL) | C11: Coupling Transformer | D11: Vendor | E11: Tesla | F11: 6497-TESL-CTF-GEN-DE-V-0002 | G11: 51H2-E-SEP-IDT-DE-G-V-0002 | H11: GA OF MARSHALLING BOX & WIRING DIAGRAM and SCHEMATIC DIAGRAM OF COOLING SYSTEM | I11: Approval | J11: Drawing | K11: 46185 | N11: {=_xlfn.IFNA(LOOKUP(2, 1/(MOD(COLUMN(O11:XFD11)-COLUMN(O11), 5)=2)/(O11:XFD11<>""), O11:XFD11),"Not Submitted")} -> Not Submitted | BM11: =MID(F11,20,1) -> E
A12: 10 | B12: =$A$1 -> PSS09_Adani Green Energy 27 A Limited (AGE27AL) | C12: Coupling Transformer | D12: Vendor | E12: Tesla | F12: 6497-TESL-CTF-GEN-DE-V-0003 | G12: 51H2-E-SEP-IDT-DE-G-V-0003 | H12: CTR NIFPS (Nitrogen Injection & Fire Protection System) Drawings | I12: Approval | J12: Drawing | K12: 46185 | N12: {=_xlfn.IFNA(LOOKUP(2, 1/(MOD(COLUMN(O12:XFD12)-COLUMN(O12), 5)=2)/(O12:XFD12<>""), O12:XFD12),"Not Submitted")} -> Not Submitted | BM12: =MID(F12,20,1) -> E
A13: 11 | B13: =$A$1 -> PSS09_Adani Green Energy 27 A Limited (AGE27AL) | C13: Coupling Transformer | D13: Vendor | E13: Tesla | F13: 6497-TESL-CTF-GEN-DE-V-0004 | G13: 51H2-E-SEP-IDT-DE-G-V-0004 | H13: ONLINE DRYING SYSTEM DRAWING WITH GUARANRTEED TECHNICAL PARTICULARS | I13: Approval | J13: Drawing | K13: 46185 | N13: {=_xlfn.IFNA(LOOKUP(2, 1/(MOD(COLUMN(O13:XFD13)-COLUMN(O13), 5)=2)/(O13:XFD13<>""), O13:XFD13),"Not Submitted")} -> Not Submitted | BM13: =MID(F13,20,1) -> E
A14: 12 | B14: =$A$1 -> PSS09_Adani Green Energy 27 A Limited (AGE27AL) | C14: Coupling Transformer | D14: Vendor | E14: Tesla | F14: 6497-TESL-CTF-GEN-DE-D-0001 | G14: 51H2-E-SEP-IDT-DE-D-V-0001 | H14: GTP of IDT | I14: Approval | J14: Document | K14: 46185 | N14: {=_xlfn.IFNA(LOOKUP(2, 1/(MOD(COLUMN(O14:XFD14)-COLUMN(O14), 5)=2)/(O14:XFD14<>""), O14:XFD14),"Not Submitted")} -> Not Submitted | BM14: =MID(F14,20,1) -> E
A15: 13 | B15: =$A$1 -> PSS09_Adani Green Energy 27 A Limited (AGE27AL) | C15: Coupling Transformer | D15: Vendor | E15: Tesla | F15: 6497-TESL-CTF-GEN-DE-M-0001 | G15: 51H2-E-SEP-IDT-DE-M-V-0001 | H15: O&M Manual of IDT | I15: Approval | J15: Document | K15: 46185 | N15: {=_xlfn.IFNA(LOOKUP(2, 1/(MOD(COLUMN(O15:XFD15)-COLUMN(O15), 5)=2)/(O15:XFD15<>""), O15:XFD15),"Not Submitted")} -> Not Submitted | BM15: =MID(F15,20,1) -> E
A16: 14 | B16: =$A$1 -> PSS09_Adani Green Energy 27 A Limited (AGE27AL) | C16: Battery | D16: Vendor | E16: CATL | F16: 6497-CATL-BTR-BCL-DE-D-0001 | G16: 51H2-E-BTR-BCL-BE-R-V-0001 | H16: GTP (Technical Paramater detail) for cell | I16: Information | J16: Document | K16: 46052 | N16: {=_xlfn.IFNA(LOOKUP(2, 1/(MOD(COLUMN(O16:XFD16)-COLUMN(O16), 5)=2)/(O16:XFD16<>""), O16:XFD16),"Not Submitted")} -> Cat. -I | Q16: Cat. -I | S16: Document received by Mr. Samrej Vahora on 23.02.2026 | BM16: =MID(F16,20,1) -> E
A17: 15 | B17: =$A$1 -> PSS09_Adani Green Energy 27 A Limited (AGE27AL) | C17: Battery | D17: Vendor | E17: CATL | F17: 6497-CATL-BTR-BCL-DE-G-0001 | G17: 51H2-E-BTR-BAR-DE-D-V-0001 | H17: General Arrangement (GA) drawing for cell | I17: Information | J17: Document | K17: 46052 | N17: {=_xlfn.IFNA(LOOKUP(2, 1/(MOD(COLUMN(O17:XFD17)-COLUMN(O17), 5)=2)/(O17:XFD17<>""), O17:XFD17),"Not Submitted")} -> Delete | Q17: Delete | S17: As per the received mail by Mr. Aditya Pratap Singh_02.02.2026 | BM17: =MID(F17,20,1) -> E
A18: 16 | B18: =$A$1 -> PSS09_Adani Green Energy 27 A Limited (AGE27AL) | C18: Battery | D18: Vendor | E18: CATL | F18: 6497-CATL-BTR-BCL-DE-R-0001 | G18: 51H2-E-BTR-BAR-DE-G-V-0001 | H18: Battery cell certification and compliance report, including detailed model numbers and test results for cell | I18: Information | J18: Drawing | K18: 46052 | L18: 46295 | N18: {=_xlfn.IFNA(LOOKUP(2, 1/(MOD(COLUMN(O18:XFD18)-COLUMN(O18), 5)=2)/(O18:XFD18<>""), O18:XFD18),"Not Submitted")} -> Not Submitted | BM18: =MID(F18,20,1) -> E
A19: 17 | B19: =$A$1 -> PSS09_Adani Green Energy 27 A Limited (AGE27AL) | C19: Battery | D19: Vendor | E19: CATL | F19: 6497-CATL-BTR-BAR-DE-D-0001 | G19: 51H2-E-BTR-BAR-BE-R-V-0001 | H19: GTP (Technical Paramater detail) (Pack, HV box and rack ) for rack | I19: Approval | J19: Document | K19: 46052 | N19: {=_xlfn.IFNA(LOOKUP(2, 1/(MOD(COLUMN(O19:XFD19)-COLUMN(O19), 5)=2)/(O19:XFD19<>""), O19:XFD19),"Not Submitted")} -> Cat. -I | Q19: Cat. -I | S19: Document received by Mr. Samrej Vahora on 23.02.2026 | BM19: =MID(F19,20,1) -> E
A20: 18 | B20: =$A$1 -> PSS09_Adani Green Energy 27 A Limited (AGE27AL) | C20: Battery | D20: Vendor | E20: CATL | F20: 6497-CATL-BTR-BAR-DE-G-0001 | G20: 51H2-E-BTR-BCN-DE-D-V-0001 | H20: GA Drawing (PDF &CAD file ) showing component layout and dimensions for rack 1- Battery Pack 2- HV box with Rack Frame | I20: Approval | J20: Document | K20: 46052 | N20: {=_xlfn.IFNA(LOOKUP(2, 1/(MOD(COLUMN(O20:XFD20)-COLUMN(O20), 5)=2)/(O20:XFD20<>""), O20:XFD20),"Not Submitted")} -> Delete | Q20: Delete | S20: As per the received mail by Mr. Aditya Pratap Singh_02.02.2026 | BM20: =MID(F20,20,1) -> E
A21: 19 | B21: =$A$1 -> PSS09_Adani Green Energy 27 A Limited (AGE27AL) | C21: Battery | D21: Vendor | E21: CATL | F21: 6497-CATL-BTR-BAR-DE-R-0001 | G21: 51H2-E-BTR-BCN-DE-G-V-0001 | H21: Certification and test report for battery rack, including model numbers and compliance data for rack | I21: Information | J21: Drawing | K21: 46052 | N21: {=_xlfn.IFNA(LOOKUP(2, 1/(MOD(COLUMN(O21:XFD21)-COLUMN(O21), 5)=2)/(O21:XFD21<>""), O21:XFD21),"Not Submitted")} -> Cat. -IV | Q21: Cat. -IV | S21: Document received by Mr. Samrej Vahora on 27.06.2026 | BM21: =MID(F21,20,1) -> E
A22: 20 | B22: =$A$1 -> PSS09_Adani Green Energy 27 A Limited (AGE27AL) | C22: Battery | D22: Vendor | E22: CATL | F22: 6497-CATL-BTR-BCN-DE-D-0001 | G22: 51H2-E-BTR-BCN-BE-R-V-0001 | H22: GTP (Technical Paramater detail) for Container | I22: Approval | J22: Document | K22: 46052 | N22: {=_xlfn.IFNA(LOOKUP(2, 1/(MOD(COLUMN(O22:XFD22)-COLUMN(O22), 5)=2)/(O22:XFD22<>""), O22:XFD22),"Not Submitted")} -> Cat. -I | Q22: Cat. -I | S22: Document received by Mr. Samrej Vahora on 23.02.2026 | BM22: =MID(F22,20,1) -> E
A23: 21 | B23: =$A$1 -> PSS09_Adani Green Energy 27 A Limited (AGE27AL) | C23: Battery | D23: Vendor | E23: CATL | F23: 6497-CATL-BTR-BCN-DE-G-0001 | G23: 51H2-E-BTR-FSS-DE-D-V-0001 | H23: General Arrangement (GA) drawing in PDF and CAD formats, including detailed footing dimensions for Container | I23: Approval | J23: Document | K23: 46052 | N23: {=_xlfn.IFNA(LOOKUP(2, 1/(MOD(COLUMN(O23:XFD23)-COLUMN(O23), 5)=2)/(O23:XFD23<>""), O23:XFD23),"Not Submitted")} -> Cat. -I | Q23: Cat. -I | S23: Document received by Mr. Samrej Vahora on 26.02.2026 | BM23: =MID(F23,20,1) -> E
A24: 22 | B24: =$A$1 -> PSS09_Adani Green Energy 27 A Limited (AGE27AL) | C24: Battery | D24: Vendor | E24: CATL | F24: 6497-CATL-BTR-BCN-DE-R-0001 | G24: 51H2-E-BTR-FSS-DE-G-V-0001 | H24: BESS container Certification and test report, including model numbers and compliance data for Container | I24: Information | J24: Drawing | K24: 46052 | N24: {=_xlfn.IFNA(LOOKUP(2, 1/(MOD(COLUMN(O24:XFD24)-COLUMN(O24), 5)=2)/(O24:XFD24<>""), O24:XFD24),"Not Submitted")} -> Cat. -IV | Q24: Cat. -IV | S24: Document received by Mr. Kunal on 23.06.2026 | BM24: =MID(F24,20,1) -> E
A25: 23 | B25: =$A$1 -> PSS09_Adani Green Energy 27 A Limited (AGE27AL) | C25: Battery | D25: Vendor | E25: CATL | F25: 6497-CATL-BTR-FSS-DE-D-0001 | G25: 51H2-E-BTR-FSS-BE-R-V-0001 | H25: GTP (Technical Paramater detail) for FSS | I25: Approval | J25: Document | K25: 46052 | N25: {=_xlfn.IFNA(LOOKUP(2, 1/(MOD(COLUMN(O25:XFD25)-COLUMN(O25), 5)=2)/(O25:XFD25<>""), O25:XFD25),"Not Submitted")} -> Cat. -I | Q25: Cat. -I | S25: Document received by Mr. Samrej Vahora on 26.02.2026 | BM25: =MID(F25,20,1) -> E
A26: 24 | B26: =$A$1 -> PSS09_Adani Green Energy 27 A Limited (AGE27AL) | C26: Battery | D26: Vendor | E26: CATL | F26: 6497-CATL-BTR-FSS-DE-G-0001 | G26: 51H2-E-BTR-DCA-DE-D-V-0001 | H26: GA FOR FSS | I26: Approval | J26: Document | K26: 46052 | N26: {=_xlfn.IFNA(LOOKUP(2, 1/(MOD(COLUMN(O26:XFD26)-COLUMN(O26), 5)=2)/(O26:XFD26<>""), O26:XFD26),"Not Submitted")} -> Delete | Q26: Delete | S26: As per the received mail by Mr. Aditya Pratap Singh_02.02.2026 | BM26: =MID(F26,20,1) -> E
A27: 25 | B27: =$A$1 -> PSS09_Adani Green Energy 27 A Limited (AGE27AL) | C27: Battery | D27: Vendor | E27: CATL | F27: 6497-CATL-BTR-FSS-DE-D-0002 | G27: 51H2-E-BTR-DCA-DE-G-V-0001 | H27: FSS component details as per given format for FSS | I27: Information | J27: Drawing | K27: 46052 | N27: {=_xlfn.IFNA(LOOKUP(2, 1/(MOD(COLUMN(O27:XFD27)-COLUMN(O27), 5)=2)/(O27:XFD27<>""), O27:XFD27),"Not Submitted")} -> Cat. -IV | Q27: Cat. -IV | S27: Document received by Mr. Samrej Vahora on 26.02.2026 | BM27: =MID(F27,20,1) -> E
A28: 26 | B28: =$A$1 -> PSS09_Adani Green Energy 27 A Limited (AGE27AL) | C28: Battery | D28: Vendor | E28: CATL | F28: 6497-CATL-BTR-FSS-DE-R-0001 | G28: 51H2-E-BTR-DCA-BE-R-V-0001 | H28: FSS Certification and test report, including model numbers,compliance data and design calculation of aerosol and venting area for FSS | I28: Information | J28: Document | K28: 46052 | N28: {=_xlfn.IFNA(LOOKUP(2, 1/(MOD(COLUMN(O28:XFD28)-COLUMN(O28), 5)=2)/(O28:XFD28<>""), O28:XFD28),"Not Submitted")} -> Cat. -IV | Q28: Cat. -IV | S28: Document received by Mr. Samrej Vahora on 09.07.2026 | BM28: =MID(F28,20,1) -> E
A29: 27 | B29: =$A$1 -> PSS09_Adani Green Energy 27 A Limited (AGE27AL) | C29: Battery | D29: Vendor | E29: CATL | F29: 6497-CATL-BTR-DCA-DE-D-0001 | G29: 51H2-E-BTR-HVA-DE-D-V-0001 | H29: GTP (Technical Paramater detail) for DC Cable Termination Cabinet | I29: Approval | J29: Document | K29: 46052 | N29: {=_xlfn.IFNA(LOOKUP(2, 1/(MOD(COLUMN(O29:XFD29)-COLUMN(O29), 5)=2)/(O29:XFD29<>""), O29:XFD29),"Not Submitted")} -> Cat. -I | Q29: Cat. -I | S29: Document received by Mr. Samrej Vahora on 23.02.2026 | BM29: =MID(F29,20,1) -> E
A30: 28 | B30: =$A$1 -> PSS09_Adani Green Energy 27 A Limited (AGE27AL) | C30: Battery | D30: Vendor | E30: CATL | F30: 6497-CATL-BTR-DCA-DE-G-0001 | G30: 51H2-E-BTR-HVA-DE-G-V-0001 | H30: GA for DC Cable Termination Cabinet 1- CAD file & PDF 2- Terminal busbar drawing include hole size and position with lug integrated (shared by adani) 3-Detailed layout showing cable entry points and termination locations | I30: Approval | J30: Drawing | K30: 46052 | N30: {=_xlfn.IFNA(LOOKUP(2, 1/(MOD(COLUMN(O30:XFD30)-COLUMN(O30), 5)=2)/(O30:XFD30<>""), O30:XFD30),"Not Submitted")} -> Cat. -I | Q30: Cat. -I | S30: Document received by Mr. Samrej Vahora on 23.02.2026 | BM30: =MID(F30,20,1) -> E
... A46: 44 | B46: =$A$1 -> PSS09_Adani Green Energy 27 A Limited (AGE27AL) | C46: Battery | D46: Vendor | E46: CATL | F46: 6497-CATL-BTR-GEN-DE-O-0002 | G46: 51H2-E-BTR-GEN-DE-D-V-0002 | H46: Model for System Design and Aux Calculation based on Ambient. | I46: Approval | J46: Document | K46: 46052 | N46: {=_xlfn.IFNA(LOOKUP(2, 1/(MOD(COLUMN(O46:XFD46)-COLUMN(O46), 5)=2)/(O46:XFD46<>""), O46:XFD46),"Not Submitted")} -> Cat. -I | Q46: Cat. -I | S46: Document received by Mr. Samrej Vahora on 23.02.2026 | BM46: =MID(F46,20,1) -> E
A47: 45 | B47: =$A$1 -> PSS09_Adani Green Energy 27 A Limited (AGE27AL) | C47: Battery | D47: Vendor | E47: CATL | F47: 6497-CATL-BTR-GEN-DE-O-0004 | G47: 51H2-E-BTR-GEN-DE-D-V-0003 | H47: Degradation profile considering cycle per day, DoD, temperature, etc. | I47: Approval | K47: 46052 | N47: {=_xlfn.IFNA(LOOKUP(2, 1/(MOD(COLUMN(O47:XFD47)-COLUMN(O47), 5)=2)/(O47:XFD47<>""), O47:XFD47),"Not Submitted")} -> Cat. -I | Q47: Cat. -I | S47: Document received by Mr. Samrej Vahora on 23.02.2026 | BM47: =MID(F47,20,1) -> E
A48: 46 | B48: =$A$1 -> PSS09_Adani Green Energy 27 A Limited (AGE27AL) | C48: Battery | D48: Vendor | E48: CATL | F48: 6497-CATL-BTR-GEN-DE-D-0001 | G48: 51H2-E-BTR-GEN-DE-O-V-0005 | H48: BESS Container Communication Interface & Scheme, Port details | I48: Information | K48: 46052 | N48: {=_xlfn.IFNA(LOOKUP(2, 1/(MOD(COLUMN(O48:XFD48)-COLUMN(O48), 5)=2)/(O48:XFD48<>""), O48:XFD48),"Not Submitted")} -> Cat. -IV | Q48: Cat. -IV | S48: Document received by Mr. Samrej Vahora on 26.02.2026 | BM48: =MID(F48,20,1) -> E
A49: 47 | B49: =$A$1 -> PSS09_Adani Green Energy 27 A Limited (AGE27AL) | C49: Battery | D49: Vendor | E49: CATL | F49: 6497-CATL-BTR-GEN-DE-M-0001 | G49: 51H2-E-BTR-GEN-DE-O-V-0006 | H49: O&M Manual and Installation & Transportation Manual | I49: Information | K49: 46052 | N49: {=_xlfn.IFNA(LOOKUP(2, 1/(MOD(COLUMN(O49:XFD49)-COLUMN(O49), 5)=2)/(O49:XFD49<>""), O49:XFD49),"Not Submitted")} -> Cat. -IV | Q49: Cat. -IV | S49: Document received by Mr. Samrej Vahora on 26.02.2026 | BM49: =MID(F49,20,1) -> E
A50: 48 | B50: =$A$1 -> PSS09_Adani Green Energy 27 A Limited (AGE27AL) | C50: Battery | D50: Vendor | E50: CATL | F50: 6497-CATL-BTR-GEN-DE-B-0001 | G50: 51H2-E-BTR-GEN-DE-N-V-0001 | H50: BOQ and spare parts list (all component list pack level, HV box, rack level, container level,etc..) | I50: Approval | K50: 46052 | N50: {=_xlfn.IFNA(LOOKUP(2, 1/(MOD(COLUMN(O50:XFD50)-COLUMN(O50), 5)=2)/(O50:XFD50<>""), O50:XFD50),"Not Submitted")} -> Cat. -IV | Q50: Cat. -IV | S50: Document received by Mr. Samrej Vahora on 27.06.2026 | BM50: =MID(F50,20,1) -> E
A51: 49 | B51: =$A$1 -> PSS09_Adani Green Energy 27 A Limited (AGE27AL) | C51: Battery | D51: Vendor | E51: CATL | F51: 6497-CATL-BTR-GEN-DE-R-0001 | G51: 51H2-E-BTR-GEN-DE-D-V-0004 | H51: Certification Summary | I51: Information | K51: 46052 | N51: {=_xlfn.IFNA(LOOKUP(2, 1/(MOD(COLUMN(O51:XFD51)-COLUMN(O51), 5)=2)/(O51:XFD51<>""), O51:XFD51),"Not Submitted")} -> Cat. -IV | Q51: Cat. -IV | S51: Document received by Mr. Samrej Vahora on 27.06.2026 | BM51: =MID(F51,20,1) -> E
A52: 50 | B52: =$A$1 -> PSS09_Adani Green Energy 27 A Limited (AGE27AL) | C52: Battery | D52: Vendor | E52: CATL | F52: 6497-CATL-BTR-GEN-DE-D-0002 | G52: 51H2-E-BTR-BCL-DE-R-V-0101 | H52: Details of BMS ethernet port for interface with EMS. | I52: Information | J52: Document | K52: 46052 | N52: {=_xlfn.IFNA(LOOKUP(2, 1/(MOD(COLUMN(O52:XFD52)-COLUMN(O52), 5)=2)/(O52:XFD52<>""), O52:XFD52),"Not Submitted")} -> Cat. -IV | Q52: Cat. -IV | S52: Document received by Mr. Krunal on 02.03.2026 | BM52: =MID(F52,20,1) -> E
A53: 51 | B53: =$A$1 -> PSS09_Adani Green Energy 27 A Limited (AGE27AL) | C53: Battery | D53: Vendor | E53: CATL | F53: 6497-CATL-BTR-GEN-DE-O-0005 | G53: 51H2-E-BTR-BAR-DE-D-V-0101 | H53: Modbus mapping register with complete description for all parameters. | I53: Information | J53: Document | K53: 46052 | N53: {=_xlfn.IFNA(LOOKUP(2, 1/(MOD(COLUMN(O53:XFD53)-COLUMN(O53), 5)=2)/(O53:XFD53<>""), O53:XFD53),"Not Submitted")} -> Cat. -IV | Q53: Cat. -IV | S53: Document received by Mr. Samrej Vahora on 26.02.2026 | BM53: =MID(F53,20,1) -> E
A54: 52 | B54: =$A$1 -> PSS09_Adani Green Energy 27 A Limited (AGE27AL) | C54: Battery | D54: Vendor | E54: CATL | F54: 6497-CATL-BTR-GEN-DE-N-0001 | G54: 51H2-E-BTR-BAR-DE-G-V-0101 | H54: BMS control philoshophy (Fail secnerios, mode of operation, Setpoints, Moderate/ mild/Severe alarm actions ) | I54: Information | J54: Drawing | K54: 46052 | N54: {=_xlfn.IFNA(LOOKUP(2, 1/(MOD(COLUMN(O54:XFD54)-COLUMN(O54), 5)=2)/(O54:XFD54<>""), O54:XFD54),"Not Submitted")} -> Cat. -IV | Q54: Cat. -IV | S54: Document received by Mr. Samrej Vahora on 23.02.2026 | BM54: =MID(F54,20,1) -> E
A55: 53 | B55: =$A$1 -> PSS09_Adani Green Energy 27 A Limited (AGE27AL) | C55: Battery | D55: Vendor | E55: CATL | F55: 6497-CATL-BTR-GEN-DE-D-0003 | G55: 51H2-E-BTR-BAR-BE-R-V-0101 | H55: BMS make and technical datasheet | I55: Information | J55: Document | K55: 46052 | N55: {=_xlfn.IFNA(LOOKUP(2, 1/(MOD(COLUMN(O55:XFD55)-COLUMN(O55), 5)=2)/(O55:XFD55<>""), O55:XFD55),"Not Submitted")} -> Cat. -IV | Q55: Cat. -IV | S55: Document received by Mr. Samrej Vahora on 23.02.2026 | BM55: =MID(F55,20,1) -> E
...

Sheet PSS08B
A1: PSS08B_Adani Renewable Energy 35 Limited (ARE35L) | O1: Rev.00 | T1: Rev.01 | Y1: Rev.02 | AD1: Rev.03 | AI1: Rev.04/0E | AN1: Rev.05/0F | AS1: Rev.06/0G | AX1: Rev.07/0H | BC1: Rev.08/0I | BH1: Rev.09/0J
A2: Sr. No. | B2: Project | C2: Package | D2: In-house/Vendor | E2: In-house/Vendor Name2 | F2: New_Drawing / Document Number | G2: Drawing / Document Number | H2: Document Title | I2: Document Category | J2: DOCUMENT TYPE | K2: Schedule Date | L2: FORECAST DATE | M2: Weightage | N2: Status | O2: Recd Date_00 | P2: Comment date_00 | Q2: Status_00 | R2: XMTL No._00 | S2: Remarks_00 | T2: Recd Date_01 | U2: Comment date_01 | V2: Status_01 | W2: XMTL No._01 | X2: Remarks_01 | Y2: Recd Date_02 | Z2: Comment date_02 | AA2: Status_02 | AB2: XMTL No._02 | AC2: Remarks_02 | AD2: Recd Date_03 | AE2: Comment date_03 | AF2: Status_03 | AG2: XMTL No._03 | AH2: Remarks_03 | AI2: Recd Date_04 | AJ2: Comment date_04 | AK2: Status_04 | AL2: XMTL No._04 | AM2: Remarks_04 | AN2: Recd Date_05 | AO2: Comment date_05 | AP2: Status_05 | AQ2: XMTL No._05 | AR2: Remarks_05 | AS2: Recd Date_06 | AT2: Comment date_06 | AU2: Status_06 | AV2: XMTL No._06 | AW2: Remarks_06 | AX2: Recd Date_07 | AY2: Comment date_07 | AZ2: Status_07 | BA2: XMTL No._07 | BB2: Remarks_07 | BC2: Recd Date_08 | BD2: Comment date_08 | BE2: Status_08 | BF2: XMTL No._08 | BG2: Remarks_08 | BH2: Recd Date_09 | BI2: Comment date_09 | BJ2: Status_09 | BK2: XMTL No._09 | BL2: Remarks_09 | BM2: Remarks_10
A3: 1 | B3: =$A$1 -> PSS08B_Adani Renewable Energy 35 Limited (ARE35L) | C3: Coupling Transformer | D3: Vendor | E3: Tesla | F3: 51N3-TESL-CTF-GEN-DE-V-0001 | G3: 51H2-E-SEP-IDT-DE-G-V-0001 | H3: GA Drawings with List of Fittings for IDT | I3: Approval | J3: Drawing | K3: 46163 | N3: {=_xlfn.IFNA(LOOKUP(2, 1/(MOD(COLUMN(O3:XFD3)-COLUMN(O3), 5)=2)/(O3:XFD3<>""), O3:XFD3),"Not Submitted")} -> Under Review | O3: 46165 | P3: 46188 | Q3: Cat. -I_Star | T3: 46202 | V3: Under Review | BM3: =MID(F3,20,1) -> E
A4: 2 | B4: =$A$1 -> PSS08B_Adani Renewable Energy 35 Limited (ARE35L) | C4: Coupling Transformer | D4: Vendor | E4: Tesla | F4: 51N3-TESL-CTF-GEN-DE-V-0002 | G4: 51H2-E-SEP-IDT-DE-G-V-0002 | H4: GA OF MARSHALLING BOX & WIRING DIAGRAM and SCHEMATIC DIAGRAM OF COOLING SYSTEM | I4: Approval | J4: Drawing | K4: 46163 | N4: {=_xlfn.IFNA(LOOKUP(2, 1/(MOD(COLUMN(O4:XFD4)-COLUMN(O4), 5)=2)/(O4:XFD4<>""), O4:XFD4),"Not Submitted")} -> Cat. -I | O4: 46165 | P4: 46188 | Q4: Cat. -I | BM4: =MID(F4,20,1) -> E
A5: 3 | B5: =$A$1 -> PSS08B_Adani Renewable Energy 35 Limited (ARE35L) | C5: Coupling Transformer | D5: Vendor | E5: Tesla | F5: 51N3-TESL-CTF-GEN-DE-V-0003 | G5: 51H2-E-SEP-IDT-DE-G-V-0003 | H5: CTR NIFPS (Nitrogen Injection & Fire Protection System) Drawings | I5: Approval | J5: Drawing | K5: 46163 | N5: {=_xlfn.IFNA(LOOKUP(2, 1/(MOD(COLUMN(O5:XFD5)-COLUMN(O5), 5)=2)/(O5:XFD5<>""), O5:XFD5),"Not Submitted")} -> Cat. -I | O5: 46165 | P5: 46188 | Q5: Cat. -I | BM5: =MID(F5,20,1) -> E
A6: 4 | B6: =$A$1 -> PSS08B_Adani Renewable Energy 35 Limited (ARE35L) | C6: Coupling Transformer | D6: Vendor | E6: Tesla | F6: 51N3-TESL-CTF-GEN-DE-V-0004 | G6: 51H2-E-SEP-IDT-DE-G-V-0004 | H6: ONLINE DRYING SYSTEM DRAWING WITH GUARANRTEED TECHNICAL PARTICULARS | I6: Approval | J6: Drawing | K6: 46163 | N6: {=_xlfn.IFNA(LOOKUP(2, 1/(MOD(COLUMN(O6:XFD6)-COLUMN(O6), 5)=2)/(O6:XFD6<>""), O6:XFD6),"Not Submitted")} -> delete | Q6: delete | BM6: =MID(F6,20,1) -> E
A7: 5 | B7: =$A$1 -> PSS08B_Adani Renewable Energy 35 Limited (ARE35L) | C7: Coupling Transformer | D7: Vendor | E7: Tesla | F7: 51N3-TESL-CTF-GEN-DE-D-0001 | G7: 51H2-E-SEP-IDT-DE-D-V-0001 | H7: GTP of IDT | I7: Approval | J7: Document | K7: 46163 | N7: {=_xlfn.IFNA(LOOKUP(2, 1/(MOD(COLUMN(O7:XFD7)-COLUMN(O7), 5)=2)/(O7:XFD7<>""), O7:XFD7),"Not Submitted")} -> Cat. -I | O7: 46165 | P7: 46188 | Q7: Cat. -I | BM7: =MID(F7,20,1) -> E
A8: 6 | B8: =$A$1 -> PSS08B_Adani Renewable Energy 35 Limited (ARE35L) | C8: Coupling Transformer | D8: Vendor | E8: Tesla | F8: 51N3-TESL-CTF-GEN-DE-M-0001 | G8: 51H2-E-SEP-IDT-DE-M-V-0001 | H8: O&M Manual of IDT | I8: Approval | J8: Document | K8: 46163 | N8: {=_xlfn.IFNA(LOOKUP(2, 1/(MOD(COLUMN(O8:XFD8)-COLUMN(O8), 5)=2)/(O8:XFD8<>""), O8:XFD8),"Not Submitted")} -> Cat. -IV | O8: 46165 | P8: 46188 | Q8: Cat. -IV | BM8: =MID(F8,20,1) -> E
A9: 11 | B9: =$A$1 -> PSS08B_Adani Renewable Energy 35 Limited (ARE35L) | C9: Coupling Transformer | D9: Vendor | E9: Ornet | F9: 51N3-ORNT-CTF-GEN-DE-V-0001 | G9: 51H2-E-SEP-IDT-DE-G-V-0001 | H9: GA Drawings with List of Fittings for IDT | I9: Approval | J9: Drawing | N9: {=_xlfn.IFNA(LOOKUP(2, 1/(MOD(COLUMN(O9:XFD9)-COLUMN(O9), 5)=2)/(O9:XFD9<>""), O9:XFD9),"Not Submitted")} -> Cat. -I | O9: 46176 | P9: 46182 | Q9: Cat. -I | S9: Submitted by mail | T9: NR | U9: 46202 | V9: Cat. -I | BM9: =MID(F9,20,1) -> E
A10: 10 | B10: =$A$1 -> PSS08B_Adani Renewable Energy 35 Limited (ARE35L) | C10: Coupling Transformer | D10: Vendor | E10: Ornet | F10: 51N3-ORNT-CTF-GEN-DE-V-0002 | G10: 51H2-E-SEP-IDT-DE-G-V-0002 | H10: GA OF MARSHALLING BOX & WIRING DIAGRAM and SCHEMATIC DIAGRAM OF COOLING SYSTEM | I10: Approval | J10: Drawing | N10: {=_xlfn.IFNA(LOOKUP(2, 1/(MOD(COLUMN(O10:XFD10)-COLUMN(O10), 5)=2)/(O10:XFD10<>""), O10:XFD10),"Not Submitted")} -> Cat. -I | O10: 46176 | P10: 46182 | Q10: Cat. -I | S10: Submitted by mail | BM10: =MID(F10,20,1) -> E
A11: 7 | B11: =$A$1 -> PSS08B_Adani Renewable Energy 35 Limited (ARE35L) | C11: Coupling Transformer | D11: Vendor | E11: Ornet | F11: 51N3-ORNT-CTF-GEN-DE-V-0003 | G11: 51H2-E-SEP-IDT-DE-G-V-0005 | H11: NIFPS (Nitrogen Injection & Fire Protection System) Drawings | I11: Approval | J11: Drawing | N11: {=_xlfn.IFNA(LOOKUP(2, 1/(MOD(COLUMN(O11:XFD11)-COLUMN(O11), 5)=2)/(O11:XFD11<>""), O11:XFD11),"Not Submitted")} -> Cat. -I | O11: 46176 | P11: 46182 | Q11: Cat. -I | S11: Submitted by mail | BM11: =MID(F11,20,1) -> E
A12: 12 | B12: =$A$1 -> PSS08B_Adani Renewable Energy 35 Limited (ARE35L) | C12: Coupling Transformer | D12: Vendor | E12: Ornet | F12: 51N3-ORNT-CTF-GEN-DE-M-0001 | G12: 51H2-E-SEP-IDT-DE-M-V-0001 | H12: O&M Manual of IDT | I12: Approval | J12: Document | N12: {=_xlfn.IFNA(LOOKUP(2, 1/(MOD(COLUMN(O12:XFD12)-COLUMN(O12), 5)=2)/(O12:XFD12<>""), O12:XFD12),"Not Submitted")} -> Cat. -IV | O12: 46176 | P12: 46182 | Q12: Cat. -IV | S12: Submitted by mail | BM12: =MID(F12,20,1) -> E
A13: 13 | B13: =$A$1 -> PSS08B_Adani Renewable Energy 35 Limited (ARE35L) | C13: Coupling Transformer | D13: Vendor | E13: Ornet | F13: 51N3-ORNT-CTF-GEN-DE-D-0001 | G13: 51H2-E-SEP-IDT-DE-D-V-0001 | H13: GTP of IDT | I13: Approval | J13: Document | N13: {=_xlfn.IFNA(LOOKUP(2, 1/(MOD(COLUMN(O13:XFD13)-COLUMN(O13), 5)=2)/(O13:XFD13<>""), O13:XFD13),"Not Submitted")} -> Cat. -I | O13: 46176 | P13: 46182 | Q13: Cat. -I | S13: Submitted by mail | BM13: =MID(F13,20,1) -> E
A14: 14 | B14: =$A$1 -> PSS08B_Adani Renewable Energy 35 Limited (ARE35L) | C14: Battery | D14: Vendor | E14: Great Power | F14: 51N3-GRTP-BTR-BCL-DE-D-0001 | G14: 51H2-E-BTR-BCL-BE-R-V-0001 | H14: GTP (Technical Paramater detail) for cell | I14: Information | J14: Document | K14: 46081 | N14: {=_xlfn.IFNA(LOOKUP(2, 1/(MOD(COLUMN(O14:XFD14)-COLUMN(O14), 5)=2)/(O14:XFD14<>""), O14:XFD14),"Not Submitted")} -> Cat. -IV | Q14: Cat. -IV | S14: Document received by Mr. Samrej Vahora on 27.06.2026 | BM14: =MID(F14,20,1) -> E
A15: 15 | B15: =$A$1 -> PSS08B_Adani Renewable Energy 35 Limited (ARE35L) | C15: Battery | D15: Vendor | E15: Great Power | F15: 51N3-GRTP-BTR-BCL-DE-G-0001 | G15: 51H2-E-BTR-BAR-DE-D-V-0001 | H15: General Arrangement (GA) drawing for cell | I15: Information | J15: Document | K15: 46081 | N15: {=_xlfn.IFNA(LOOKUP(2, 1/(MOD(COLUMN(O15:XFD15)-COLUMN(O15), 5)=2)/(O15:XFD15<>""), O15:XFD15),"Not Submitted")} -> Cat. -IV | Q15: Cat. -IV | S15: Document received by Mr. Krunalkumar Patel on 09.03.2026 | BM15: =MID(F15,20,1) -> E
A16: 16 | B16: =$A$1 -> PSS08B_Adani Renewable Energy 35 Limited (ARE35L) | C16: Battery | D16: Vendor | E16: Great Power | F16: 51N3-GRTP-BTR-BCL-DE-R-0001 | G16: 51H2-E-BTR-BAR-DE-G-V-0001 | H16: Battery cell certification and compliance report, including detailed model numbers and test results for cell | I16: Information | J16: Drawing | K16: 46081 | N16: {=_xlfn.IFNA(LOOKUP(2, 1/(MOD(COLUMN(O16:XFD16)-COLUMN(O16), 5)=2)/(O16:XFD16<>""), O16:XFD16),"Not Submitted")} -> Cat. -IV | Q16: Cat. -IV | S16: Document received by Mr. Krunalkumar Patel on 17.03.2026 | BM16: =MID(F16,20,1) -> E
A17: 17 | B17: =$A$1 -> PSS08B_Adani Renewable Energy 35 Limited (ARE35L) | C17: Battery | D17: Vendor | E17: Great Power | F17: 51N3-GRTP-BTR-BAR-DE-D-0001 | G17: 51H2-E-BTR-BAR-BE-R-V-0001 | H17: GTP (Technical Paramater detail) (Pack, HV box and rack ) for rack | I17: Approval | J17: Document | K17: 46081 | N17: {=_xlfn.IFNA(LOOKUP(2, 1/(MOD(COLUMN(O17:XFD17)-COLUMN(O17), 5)=2)/(O17:XFD17<>""), O17:XFD17),"Not Submitted")} -> Cat. -I | Q17: Cat. -I | S17: Document received by Mr. Krunalkumar Patel on 09.03.2026 | BM17: =MID(F17,20,1) -> E
A18: 18 | B18: =$A$1 -> PSS08B_Adani Renewable Energy 35 Limited (ARE35L) | C18: Battery | D18: Vendor | E18: Great Power | F18: 51N3-GRTP-BTR-BAR-DE-G-0001 | G18: 51H2-E-BTR-BCN-DE-D-V-0001 | H18: GA Drawing (PDF &CAD file ) showing component layout and dimensions for rack 1- Battery Pack 2- HV box with Rack Frame | I18: Approval | J18: Document | K18: 46081 | N18: {=_xlfn.IFNA(LOOKUP(2, 1/(MOD(COLUMN(O18:XFD18)-COLUMN(O18), 5)=2)/(O18:XFD18<>""), O18:XFD18),"Not Submitted")} -> Cat. -I | Q18: Cat. -I | S18: Document received by Mr. Krunalkumar Patel on 09.03.2026 | BM18: =MID(F18,20,1) -> E
A19: 19 | B19: =$A$1 -> PSS08B_Adani Renewable Energy 35 Limited (ARE35L) | C19: Battery | D19: Vendor | E19: Great Power | F19: 51N3-GRTP-BTR-BAR-DE-R-0001 | G19: 51H2-E-BTR-BCN-DE-G-V-0001 | H19: Certification and test report for battery rack, including model numbers and compliance data for rack | I19: Information | J19: Drawing | K19: 46081 | N19: {=_xlfn.IFNA(LOOKUP(2, 1/(MOD(COLUMN(O19:XFD19)-COLUMN(O19), 5)=2)/(O19:XFD19<>""), O19:XFD19),"Not Submitted")} -> Cat. -IV | Q19: Cat. -IV | S19: Document received by Mr. Krunalkumar Patel on 17.03.2026 | BM19: =MID(F19,20,1) -> E
A20: 20 | B20: =$A$1 -> PSS08B_Adani Renewable Energy 35 Limited (ARE35L) | C20: Battery | D20: Vendor | E20: Great Power | F20: 51N3-GRTP-BTR-BCN-DE-D-0001 | G20: 51H2-E-BTR-BCN-BE-R-V-0001 | H20: GTP (Technical Paramater detail) for Container | I20: Approval | J20: Document | K20: 46081 | N20: {=_xlfn.IFNA(LOOKUP(2, 1/(MOD(COLUMN(O20:XFD20)-COLUMN(O20), 5)=2)/(O20:XFD20<>""), O20:XFD20),"Not Submitted")} -> Cat. -I | Q20: Cat. -I | BM20: =MID(F20,20,1) -> E
A21: 21 | B21: =$A$1 -> PSS08B_Adani Renewable Energy 35 Limited (ARE35L) | C21: Battery | D21: Vendor | E21: Great Power | F21: 51N3-GRTP-BTR-BCN-DE-G-0001 | G21: 51H2-E-BTR-FSS-DE-D-V-0001 | H21: General Arrangement (GA) drawing in PDF and CAD formats, including detailed footing dimensions for Container | I21: Approval | J21: Document | K21: 46081 | N21: {=_xlfn.IFNA(LOOKUP(2, 1/(MOD(COLUMN(O21:XFD21)-COLUMN(O21), 5)=2)/(O21:XFD21<>""), O21:XFD21),"Not Submitted")} -> Cat. -I | Q21: Cat. -I | S21: Document received by Mr. Krunalkumar Patel on 09.03.2026 | BM21: =MID(F21,20,1) -> E
A22: 22 | B22: =$A$1 -> PSS08B_Adani Renewable Energy 35 Limited (ARE35L) | C22: Battery | D22: Vendor | E22: Great Power | F22: 51N3-GRTP-BTR-BCN-DE-R-0001 | G22: 51H2-E-BTR-FSS-DE-G-V-0001 | H22: BESS container Certification and test report, including model numbers and compliance data for Container | I22: Information | J22: Drawing | K22: 46081 | N22: {=_xlfn.IFNA(LOOKUP(2, 1/(MOD(COLUMN(O22:XFD22)-COLUMN(O22), 5)=2)/(O22:XFD22<>""), O22:XFD22),"Not Submitted")} -> Cat. -IV | Q22: Cat. -IV | S22: Document received by Mr. Krunalkumar Patel on 17.03.2026 | BM22: =MID(F22,20,1) -> E
A23: 23 | B23: =$A$1 -> PSS08B_Adani Renewable Energy 35 Limited (ARE35L) | C23: Battery | D23: Vendor | E23: Great Power | F23: 51N3-GRTP-BTR-FSS-DE-D-0001 | G23: 51H2-E-BTR-FSS-BE-R-V-0001 | H23: GTP (Technical Paramater detail) for FSS | I23: Approval | J23: Document | K23: 46081 | N23: {=_xlfn.IFNA(LOOKUP(2, 1/(MOD(COLUMN(O23:XFD23)-COLUMN(O23), 5)=2)/(O23:XFD23<>""), O23:XFD23),"Not Submitted")} -> Cat. -I | Q23: Cat. -I | S23: Document received by Mr. Samrej Vahora on 24.03.2026 | BM23: =MID(F23,20,1) -> E
A24: 24 | B24: =$A$1 -> PSS08B_Adani Renewable Energy 35 Limited (ARE35L) | C24: Battery | D24: Vendor | E24: Great Power | F24: 51N3-GRTP-BTR-FSS-DE-G-0001 | G24: 51H2-E-BTR-DCA-DE-D-V-0001 | H24: GA FOR FSS | I24: Approval | J24: Document | K24: 46081 | N24: {=_xlfn.IFNA(LOOKUP(2, 1/(MOD(COLUMN(O24:XFD24)-COLUMN(O24), 5)=2)/(O24:XFD24<>""), O24:XFD24),"Not Submitted")} -> Cat. -I | Q24: Cat. -I | S24: Document received by Mr. Samrej Vahora on 24.03.2026 | BM24: =MID(F24,20,1) -> E
A25: 25 | B25: =$A$1 -> PSS08B_Adani Renewable Energy 35 Limited (ARE35L) | C25: Battery | D25: Vendor | E25: Great Power | F25: 51N3-GRTP-BTR-FSS-DE-D-0002 | G25: 51H2-E-BTR-DCA-DE-G-V-0001 | H25: FSS component details as per given format for FSS | I25: Information | J25: Drawing | K25: 46081 | N25: {=_xlfn.IFNA(LOOKUP(2, 1/(MOD(COLUMN(O25:XFD25)-COLUMN(O25), 5)=2)/(O25:XFD25<>""), O25:XFD25),"Not Submitted")} -> Cat. -IV | Q25: Cat. -IV | S25: Document received by Mr. Samrej Vahora on 16.04.2026 | BM25: =MID(F25,20,1) -> E
A26: 26 | B26: =$A$1 -> PSS08B_Adani Renewable Energy 35 Limited (ARE35L) | C26: Battery | D26: Vendor | E26: Great Power | F26: 51N3-GRTP-BTR-FSS-DE-R-0001 | G26: 51H2-E-BTR-DCA-BE-R-V-0001 | H26: FSS Certification and test report, including model numbers,compliance data and design calculation of aerosol and venting area for FSS | I26: Information | J26: Document | K26: 46081 | N26: {=_xlfn.IFNA(LOOKUP(2, 1/(MOD(COLUMN(O26:XFD26)-COLUMN(O26), 5)=2)/(O26:XFD26<>""), O26:XFD26),"Not Submitted")} -> Cat. -IV | Q26: Cat. -IV | S26: Document received by Mr. Krunalkumar Patel on 17.03.2026 | BM26: =MID(F26,20,1) -> E
A27: 27 | B27: =$A$1 -> PSS08B_Adani Renewable Energy 35 Limited (ARE35L) | C27: Battery | D27: Vendor | E27: Great Power | F27: 51N3-GRTP-BTR-DCA-DE-D-0001 | G27: 51H2-E-BTR-HVA-DE-D-V-0001 | H27: GTP (Technical Paramater detail) for DC Cable Termination Cabinet | I27: Approval | J27: Document | K27: 46081 | N27: {=_xlfn.IFNA(LOOKUP(2, 1/(MOD(COLUMN(O27:XFD27)-COLUMN(O27), 5)=2)/(O27:XFD27<>""), O27:XFD27),"Not Submitted")} -> Cat. -I | Q27: Cat. -I | S27: Document received by Mr. Krunalkumar Patel on 09.03.2026 | BM27: =MID(F27,20,1) -> E
A28: 28 | B28: =$A$1 -> PSS08B_Adani Renewable Energy 35 Limited (ARE35L) | C28: Battery | D28: Vendor | E28: Great Power | F28: 51N3-GRTP-BTR-DCA-DE-G-0001 | G28: 51H2-E-BTR-HVA-DE-G-V-0001 | H28: GA for DC Cable Termination Cabinet 1- CAD file & PDF 2- Terminal busbar drawing include hole size and position with lug integrated (shared by adani) 3-Detailed layout showing cable entry points and termination locations | I28: Approval | J28: Drawing | K28: 46081 | N28: {=_xlfn.IFNA(LOOKUP(2, 1/(MOD(COLUMN(O28:XFD28)-COLUMN(O28), 5)=2)/(O28:XFD28<>""), O28:XFD28),"Not Submitted")} -> Cat. -I | Q28: Cat. -I | S28: Document received by Mr. Krunalkumar Patel on 17.03.2026 | BM28: =MID(F28,20,1) -> E
A29: 29 | B29: =$A$1 -> PSS08B_Adani Renewable Energy 35 Limited (ARE35L) | C29: Battery | D29: Vendor | E29: Great Power | F29: 51N3-GRTP-BTR-DCA-DE-R-0001 | G29: 51H2-E-BTR-HVA-BE-R-V-0001 | H29: DC cable Termination component (Fuse, Breaker,SPD) Certification and test report, including model numbers and compliance data for DC Cable Termination Cabinet | I29: Information | J29: Document | K29: 46081 | N29: {=_xlfn.IFNA(LOOKUP(2, 1/(MOD(COLUMN(O29:XFD29)-COLUMN(O29), 5)=2)/(O29:XFD29<>""), O29:XFD29),"Not Submitted")} -> Cat. -IV | Q29: Cat. -IV | S29: Document received by Mr. Krunalkumar Patel on 09.03.2026 | BM29: =MID(F29,20,1) -> E
A30: 30 | B30: =$A$1 -> PSS08B_Adani Renewable Energy 35 Limited (ARE35L) | C30: Battery | D30: Vendor | E30: Great Power | F30: 51N3-GRTP-BTR-HVA-DE-D-0001 | G30: 51H2-E-BTR-LCO-DE-D-V-0001 | H30: GTP (Technical Paramater detail) for HVAC | I30: Approval | J30: Document | K30: 46081 | N30: {=_xlfn.IFNA(LOOKUP(2, 1/(MOD(COLUMN(O30:XFD30)-COLUMN(O30), 5)=2)/(O30:XFD30<>""), O30:XFD30),"Not Submitted")} -> Cat. -I | Q30: Cat. -I | S30: Document received by Mr. Samrej Vahora on 24.03.2026 | BM30: =MID(F30,20,1) -> E
A31: 31 | B31: =$A$1 -> PSS08B_Adani Renewable Energy 35 Limited (ARE35L) | C31: Battery | D31: Vendor | E31: Great Power | F31: 51N3-GRTP-BTR-HVA-DE-G-0001 | G31: 51H2-E-BTR-LCO-DE-G-V-0001 | H31: GA for HVAC | I31: Information | J31: Drawing | K31: 46081 | N31: {=_xlfn.IFNA(LOOKUP(2, 1/(MOD(COLUMN(O31:XFD31)-COLUMN(O31), 5)=2)/(O31:XFD31<>""), O31:XFD31),"Not Submitted")} -> Cat. -I | Q31: Cat. -I | S31: Document received by Mr. Samrej Vahora on 24.03.2026 | BM31: =MID(F31,20,1) -> E
A32: 32 | B32: =$A$1 -> PSS08B_Adani Renewable Energy 35 Limited (ARE35L) | C32: Battery | D32: Vendor | E32: Great Power | F32: 51N3-GRTP-BTR-HVA-DE-R-0001 | G32: 51H2-E-BTR-LCO-BE-R-V-0001 | H32: Certification including model numbers and compliance data for HVAC | I32: Information | J32: Document | K32: 46081 | N32: {=_xlfn.IFNA(LOOKUP(2, 1/(MOD(COLUMN(O32:XFD32)-COLUMN(O32), 5)=2)/(O32:XFD32<>""), O32:XFD32),"Not Submitted")} -> Cat. -IV | Q32: Cat. -IV | S32: Document received by Mr. Krunalkumar Patel on 09.03.2026 | BM32: =MID(F32,20,1) -> E
... A44: 44 | B44: =$A$1 -> PSS08B_Adani Renewable Energy 35 Limited (ARE35L) | C44: Battery | D44: Vendor | E44: Great Power | F44: 51N3-GRTP-BTR-GEN-DE-O-0002 | G44: 51H2-E-BTR-GEN-DE-D-V-0002 | H44: Model for System Design and Aux Calculation based on Ambient. | I44: Approval | J44: Document | K44: 46081 | N44: {=_xlfn.IFNA(LOOKUP(2, 1/(MOD(COLUMN(O44:XFD44)-COLUMN(O44), 5)=2)/(O44:XFD44<>""), O44:XFD44),"Not Submitted")} -> Cat. -I | Q44: Cat. -I | S44: Document received by Mr. Krunalkumar Patel on 09.03.2026 | BM44: =MID(F44,20,1) -> E
A45: 45 | B45: =$A$1 -> PSS08B_Adani Renewable Energy 35 Limited (ARE35L) | C45: Battery | D45: Vendor | E45: Great Power | F45: 51N3-GRTP-BTR-GEN-DE-O-0004 | G45: 51H2-E-BTR-GEN-DE-D-V-0003 | H45: Degradation profile considering cycle per day, DoD, temperature, etc. | I45: Approval | K45: 46081 | N45: {=_xlfn.IFNA(LOOKUP(2, 1/(MOD(COLUMN(O45:XFD45)-COLUMN(O45), 5)=2)/(O45:XFD45<>""), O45:XFD45),"Not Submitted")} -> Cat. -I | Q45: Cat. -I | S45: Document received by Mr. Krunalkumar Patel on 17.03.2026 | BM45: =MID(F45,20,1) -> E
A46: 46 | B46: =$A$1 -> PSS08B_Adani Renewable Energy 35 Limited (ARE35L) | C46: Battery | D46: Vendor | E46: Great Power | F46: 51N3-GRTP-BTR-GEN-DE-D-0001 | G46: 51H2-E-BTR-GEN-DE-O-V-0005 | H46: BESS Container Communication Interface & Scheme, Port details | I46: Information | K46: 46081 | N46: {=_xlfn.IFNA(LOOKUP(2, 1/(MOD(COLUMN(O46:XFD46)-COLUMN(O46), 5)=2)/(O46:XFD46<>""), O46:XFD46),"Not Submitted")} -> Cat. -IV | Q46: Cat. -IV | S46: Document received by Mr. Krunalkumar Patel on 17.03.2026 | BM46: =MID(F46,20,1) -> E
A47: 47 | B47: =$A$1 -> PSS08B_Adani Renewable Energy 35 Limited (ARE35L) | C47: Battery | D47: Vendor | E47: Great Power | F47: 51N3-GRTP-BTR-GEN-DE-M-0001 | G47: 51H2-E-BTR-GEN-DE-O-V-0006 | H47: O&M Manual and Installation & Transportation Manual | I47: Information | K47: 46081 | N47: {=_xlfn.IFNA(LOOKUP(2, 1/(MOD(COLUMN(O47:XFD47)-COLUMN(O47), 5)=2)/(O47:XFD47<>""), O47:XFD47),"Not Submitted")} -> Cat. -IV | Q47: Cat. -IV | S47: Document received by Mr. Krunalkumar Patel on 17.03.2026 | BM47: =MID(F47,20,1) -> E
A48: 48 | B48: =$A$1 -> PSS08B_Adani Renewable Energy 35 Limited (ARE35L) | C48: Battery | D48: Vendor | E48: Great Power | F48: 51N3-GRTP-BTR-GEN-DE-B-0001 | G48: 51H2-E-BTR-GEN-DE-N-V-0001 | H48: BOQ and spare parts list (all component list pack level, HV box, rack level, container level,etc..) | I48: Approval | K48: 46081 | N48: {=_xlfn.IFNA(LOOKUP(2, 1/(MOD(COLUMN(O48:XFD48)-COLUMN(O48), 5)=2)/(O48:XFD48<>""), O48:XFD48),"Not Submitted")} -> Cat. -I | Q48: Cat. -I | S48: Document received by Mr. Samrej Vahora on 24.03.2026 | BM48: =MID(F48,20,1) -> E
A49: 49 | B49: =$A$1 -> PSS08B_Adani Renewable Energy 35 Limited (ARE35L) | C49: Battery | D49: Vendor | E49: Great Power | F49: 51N3-GRTP-BTR-GEN-DE-R-0001 | G49: 51H2-E-BTR-GEN-DE-D-V-0004 | H49: Certification Summary | I49: Information | K49: 46081 | N49: {=_xlfn.IFNA(LOOKUP(2, 1/(MOD(COLUMN(O49:XFD49)-COLUMN(O49), 5)=2)/(O49:XFD49<>""), O49:XFD49),"Not Submitted")} -> Cat. -IV | Q49: Cat. -IV | S49: Document received by Mr. Krunalkumar Patel on 17.03.2026 | BM49: =MID(F49,20,1) -> E
A50: 50 | B50: =$A$1 -> PSS08B_Adani Renewable Energy 35 Limited (ARE35L) | C50: Battery | D50: Vendor | E50: Great Power | F50: 51N3-GRTP-BTR-GEN-DE-D-0002 | G50: 51H2-E-BTR-BCL-DE-R-V-0101 | H50: Details of BMS ethernet port for interface with EMS. | I50: Information | J50: Document | K50: 46081 | N50: {=_xlfn.IFNA(LOOKUP(2, 1/(MOD(COLUMN(O50:XFD50)-COLUMN(O50), 5)=2)/(O50:XFD50<>""), O50:XFD50),"Not Submitted")} -> Cat. -IV | Q50: Cat. -IV | S50: Document received by Mr. Krunalkumar Patel on 17.03.2026 | BM50: =MID(F50,20,1) -> E
A51: 51 | B51: =$A$1 -> PSS08B_Adani Renewable Energy 35 Limited (ARE35L) | C51: Battery | D51: Vendor | E51: Great Power | F51: 51N3-GRTP-BTR-GEN-DE-O-0005 | G51: 51H2-E-BTR-BAR-DE-D-V-0101 | H51: Modbus mapping register with complete description for all parameters. | I51: Information | J51: Document | K51: 46081 | N51: {=_xlfn.IFNA(LOOKUP(2, 1/(MOD(COLUMN(O51:XFD51)-COLUMN(O51), 5)=2)/(O51:XFD51<>""), O51:XFD51),"Not Submitted")} -> Cat. -IV | Q51: Cat. -IV | S51: Document received by Mr. Krunalkumar Patel on 17.03.2026 | BM51: =MID(F51,20,1) -> E
...

Sheet PSS10B
A1: PSS10B_Adani Renewable Energy 35 Limited (ARE35L) | O1: Rev.00 | T1: Rev.01 | Y1: Rev.02 | AD1: Rev.03 | AI1: Rev.04/0E | AN1: Rev.05/0F | AS1: Rev.06/0G | AX1: Rev.07/0H | BC1: Rev.08/0I | BH1: Rev.09/0J
A2: Sr. No. | B2: Project | C2: Package | D2: In-house/Vendor | E2: In-house/Vendor Name2 | F2: New_Drawing / Document Number | G2: Drawing / Document Number | H2: Document Title | I2: Document Category | J2: DOCUMENT TYPE | K2: Schedule Date | L2: FORECAST DATE | M2: Weightage | N2: Status | O2: Recd Date_00 | P2: Comment date_00 | Q2: Status_00 | R2: XMTL No._00 | S2: Remarks_00 | T2: Recd Date_01 | U2: Comment date_01 | V2: Status_01 | W2: XMTL No._01 | X2: Remarks_01 | Y2: Recd Date_02 | Z2: Comment date_02 | AA2: Status_02 | AB2: XMTL No._02 | AC2: Remarks_02 | AD2: Recd Date_03 | AE2: Comment date_03 | AF2: Status_03 | AG2: XMTL No._03 | AH2: Remarks_03 | AI2: Recd Date_04 | AJ2: Comment date_04 | AK2: Status_04 | AL2: XMTL No._04 | AM2: Remarks_04 | AN2: Recd Date_05 | AO2: Comment date_05 | AP2: Status_05 | AQ2: XMTL No._05 | AR2: Remarks_05 | AS2: Recd Date_06 | AT2: Comment date_06 | AU2: Status_06 | AV2: XMTL No._06 | AW2: Remarks_06 | AX2: Recd Date_07 | AY2: Comment date_07 | AZ2: Status_07 | BA2: XMTL No._07 | BB2: Remarks_07 | BC2: Recd Date_08 | BD2: Comment date_08 | BE2: Status_08 | BF2: XMTL No._08 | BG2: Remarks_08 | BH2: Recd Date_09 | BI2: Comment date_09 | BJ2: Status_09 | BK2: XMTL No._09 | BL2: Remarks_09 | BM2: Remarks_10
A3: 1 | B3: =$A$1 -> PSS10B_Adani Renewable Energy 35 Limited (ARE35L) | C3: Coupling Transformer | D3: Vendor | E3: Ornet | F3: 51N2-ORNT-CTF-GEN-DE-G-0001 | G3: 51H2-E-SEP-IDT-DE-G-V-0001 | H3: GA Drawings with List of Fittings for IDT | I3: Approval | J3: Drawing | N3: {=_xlfn.IFNA(LOOKUP(2, 1/(MOD(COLUMN(O3:XFD3)-COLUMN(O3), 5)=2)/(O3:XFD3<>""), O3:XFD3),"Not Submitted")} -> Cat. -I | O3: NR | T3: 46049 | U3: 46055 | V3: Cat. -I | W3: 51N2-BESS-SITE-T-0021 | BM3: =MID(F3,20,1) -> E
A4: 2 | B4: =$A$1 -> PSS10B_Adani Renewable Energy 35 Limited (ARE35L) | C4: Coupling Transformer | D4: Vendor | E4: Ornet | F4: 51N2-ORNT-CTF-GEN-DE-G-0002 | G4: 51H2-E-SEP-IDT-DE-G-V-0002 | H4: GA OF MARSHALLING BOX & WIRING DIAGRAM and SCHEMATIC DIAGRAM OF COOLING SYSTEM | I4: Approval | J4: Drawing | N4: {=_xlfn.IFNA(LOOKUP(2, 1/(MOD(COLUMN(O4:XFD4)-COLUMN(O4), 5)=2)/(O4:XFD4<>""), O4:XFD4),"Not Submitted")} -> Cat. -I | O4: NR | T4: 46049 | U4: 46055 | V4: Cat. -I | W4: 51N2-BESS-SITE-T-0021 | BM4: =MID(F4,20,1) -> E
A5: 3 | B5: =$A$1 -> PSS10B_Adani Renewable Energy 35 Limited (ARE35L) | C5: Coupling Transformer | D5: Vendor | E5: Ornet | F5: 51N2-ORNT-CTF-GEN-DE-G-0003 | G5: 51H2-E-SEP-IDT-DE-G-V-0003 | H5: EMR NIFPS (Nitrogen Injection & Fire Protection System) Drawings | I5: Approval | J5: Drawing | N5: {=_xlfn.IFNA(LOOKUP(2, 1/(MOD(COLUMN(O5:XFD5)-COLUMN(O5), 5)=2)/(O5:XFD5<>""), O5:XFD5),"Not Submitted")} -> Cat. -I | O5: NR | T5: NR | U5: 46079 | V5: Cat. -I | W5: XXXX-BESS-SITE-T-0001 | BM5: =MID(F5,20,1) -> E
A6: 4 | B6: =$A$1 -> PSS10B_Adani Renewable Energy 35 Limited (ARE35L) | C6: Coupling Transformer | D6: Vendor | E6: Ornet | F6: 51N2-ORNT-CTF-GEN-DE-G-0004 | G6: 51H2-E-SEP-IDT-DE-G-V-0004 | H6: ONLINE DRYING SYSTEM DRAWING WITH GUARANRTEED TECHNICAL PARTICULARS | I6: Approval | J6: Drawing | N6: {=_xlfn.IFNA(LOOKUP(2, 1/(MOD(COLUMN(O6:XFD6)-COLUMN(O6), 5)=2)/(O6:XFD6<>""), O6:XFD6),"Not Submitted")} -> Not Submitted | BM6: =MID(F6,20,1) -> E
A7: 5 | B7: =$A$1 -> PSS10B_Adani Renewable Energy 35 Limited (ARE35L) | C7: Coupling Transformer | D7: Vendor | E7: Ornet | F7: 51N2-ORNT-CTF-GEN-DE-G-0005 | G7: 51H2-E-SEP-IDT-DE-G-V-0005 | H7: CTR NIFPS (Nitrogen Injection & Fire Protection System) Drawings | I7: Approval | J7: Drawing | N7: {=_xlfn.IFNA(LOOKUP(2, 1/(MOD(COLUMN(O7:XFD7)-COLUMN(O7), 5)=2)/(O7:XFD7<>""), O7:XFD7),"Not Submitted")} -> Delete | Q7: Delete | BM7: =MID(F7,20,1) -> E
A8: 6 | B8: =$A$1 -> PSS10B_Adani Renewable Energy 35 Limited (ARE35L) | C8: Coupling Transformer | D8: Vendor | E8: Ornet | F8: 51N2-ORNT-CTF-GEN-DE-D-0001 | G8: 51H2-E-SEP-IDT-DE-D-V-0001 | H8: GTP of IDT | I8: Approval | J8: Document | N8: {=_xlfn.IFNA(LOOKUP(2, 1/(MOD(COLUMN(O8:XFD8)-COLUMN(O8), 5)=2)/(O8:XFD8<>""), O8:XFD8),"Not Submitted")} -> Cat. -I | O8: NR | T8: 46049 | U8: 46055 | V8: Cat. -I | W8: 51N2-BESS-SITE-T-0021 | BM8: =MID(F8,20,1) -> E
A9: 7 | B9: =$A$1 -> PSS10B_Adani Renewable Energy 35 Limited (ARE35L) | C9: Coupling Transformer | D9: Vendor | E9: Ornet | F9: 51N2-ORNT-CTF-GEN-DE-M-0001 | G9: 51H2-E-SEP-IDT-DE-M-V-0001 | H9: O&M Manual of IDT | I9: Approval | J9: Document | N9: {=_xlfn.IFNA(LOOKUP(2, 1/(MOD(COLUMN(O9:XFD9)-COLUMN(O9), 5)=2)/(O9:XFD9<>""), O9:XFD9),"Not Submitted")} -> Cat. -IV | O9: NR | P9: 46079 | Q9: Cat. -IV | R9: XXXX-BESS-SITE-T-0001 | BM9: =MID(F9,20,1) -> E
A10: 8 | B10: =$A$1 -> PSS10B_Adani Renewable Energy 35 Limited (ARE35L) | C10: Coupling Transformer | D10: Vendor | E10: Tesla | F10: 51N2-TESL-CTF-GEN-DE-G-0001 | G10: 51H2-E-SEP-IDT-DE-G-V-0001 | H10: GA Drawings with List of Fittings for IDT | I10: Approval | J10: Drawing | N10: {=_xlfn.IFNA(LOOKUP(2, 1/(MOD(COLUMN(O10:XFD10)-COLUMN(O10), 5)=2)/(O10:XFD10<>""), O10:XFD10),"Not Submitted")} -> Cat. -I | O10: NR | P10: 46042 | Q10: Cat. -I | R10: 51N2-BESS-SITE-T-0011 | S10: rev.02 | BM10: =MID(F10,20,1) -> E
A11: 9 | B11: =$A$1 -> PSS10B_Adani Renewable Energy 35 Limited (ARE35L) | C11: Coupling Transformer | D11: Vendor | E11: Tesla | F11: 51N2-TESL-CTF-GEN-DE-G-0002 | G11: 51H2-E-SEP-IDT-DE-G-V-0002 | H11: GA OF MARSHALLING BOX & WIRING DIAGRAM and SCHEMATIC DIAGRAM OF COOLING SYSTEM | I11: Approval | J11: Drawing | N11: {=_xlfn.IFNA(LOOKUP(2, 1/(MOD(COLUMN(O11:XFD11)-COLUMN(O11), 5)=2)/(O11:XFD11<>""), O11:XFD11),"Not Submitted")} -> Cat. -I | O11: NR | P11: 46042 | Q11: Cat. -I | R11: 51N2-BESS-SITE-T-0011 | S11: reV.01 | BM11: =MID(F11,20,1) -> E
A12: 10 | B12: =$A$1 -> PSS10B_Adani Renewable Energy 35 Limited (ARE35L) | C12: Coupling Transformer | D12: Vendor | E12: Tesla | F12: 51N2-TESL-CTF-GEN-DE-G-0003 | G12: 51H2-E-SEP-IDT-DE-G-V-0003 | H12: EMR NIFPS (Nitrogen Injection & Fire Protection System) Drawings | I12: Approval | J12: Drawing | N12: {=_xlfn.IFNA(LOOKUP(2, 1/(MOD(COLUMN(O12:XFD12)-COLUMN(O12), 5)=2)/(O12:XFD12<>""), O12:XFD12),"Not Submitted")} -> Not Submitted | BM12: =MID(F12,20,1) -> E
A13: 11 | B13: =$A$1 -> PSS10B_Adani Renewable Energy 35 Limited (ARE35L) | C13: Coupling Transformer | D13: Vendor | E13: Tesla | F13: 51N2-TESL-CTF-GEN-DE-G-0004 | G13: 51H2-E-SEP-IDT-DE-G-V-0004 | H13: ONLINE DRYING SYSTEM DRAWING WITH GUARANRTEED TECHNICAL PARTICULARS | I13: Approval | J13: Drawing | N13: {=_xlfn.IFNA(LOOKUP(2, 1/(MOD(COLUMN(O13:XFD13)-COLUMN(O13), 5)=2)/(O13:XFD13<>""), O13:XFD13),"Not Submitted")} -> Not Submitted | BM13: =MID(F13,20,1) -> E
A14: 12 | B14: =$A$1 -> PSS10B_Adani Renewable Energy 35 Limited (ARE35L) | C14: Coupling Transformer | D14: Vendor | E14: Tesla | F14: 51N2-TESL-CTF-GEN-DE-G-0005 | G14: 51H2-E-SEP-IDT-DE-G-V-0005 | H14: CTR NIFPS (Nitrogen Injection & Fire Protection System) Drawings | I14: Approval | J14: Drawing | N14: {=_xlfn.IFNA(LOOKUP(2, 1/(MOD(COLUMN(O14:XFD14)-COLUMN(O14), 5)=2)/(O14:XFD14<>""), O14:XFD14),"Not Submitted")} -> Not Submitted | BM14: =MID(F14,20,1) -> E
A15: 13 | B15: =$A$1 -> PSS10B_Adani Renewable Energy 35 Limited (ARE35L) | C15: Coupling Transformer | D15: Vendor | E15: Tesla | F15: 51N2-TESL-CTF-GEN-DE-D-0001 | G15: 51H2-E-SEP-IDT-DE-D-V-0001 | H15: GTP of IDT | I15: Approval | J15: Document | N15: {=_xlfn.IFNA(LOOKUP(2, 1/(MOD(COLUMN(O15:XFD15)-COLUMN(O15), 5)=2)/(O15:XFD15<>""), O15:XFD15),"Not Submitted")} -> Cat. -I | O15: NR | P15: 46042 | Q15: Cat. -I | R15: 51N2-BESS-SITE-T-0011 | BM15: =MID(F15,20,1) -> E
A16: 14 | B16: =$A$1 -> PSS10B_Adani Renewable Energy 35 Limited (ARE35L) | C16: Coupling Transformer | D16: Vendor | E16: Tesla | F16: 51N2-TESL-CTF-GEN-DE-M-0001 | G16: 51H2-E-SEP-IDT-DE-M-V-0001 | H16: O&M Manual of IDT | I16: Approval | J16: Document | N16: {=_xlfn.IFNA(LOOKUP(2, 1/(MOD(COLUMN(O16:XFD16)-COLUMN(O16), 5)=2)/(O16:XFD16<>""), O16:XFD16),"Not Submitted")} -> Not Submitted | BM16: =MID(F16,20,1) -> E
A17: 15 | B17: =$A$1 -> PSS10B_Adani Renewable Energy 35 Limited (ARE35L) | C17: Battery | D17: Vendor | E17: Jinco | F17: 51N2-JNCO-BTR-BCL-DE-D-0001 | G17: 51H2-E-BTR-BCL-BE-R-V-0001 | H17: GTP (Technical Paramater detail) for cell | I17: Information | J17: Document | K17: 46052 | N17: {=_xlfn.IFNA(LOOKUP(2, 1/(MOD(COLUMN(O17:XFD17)-COLUMN(O17), 5)=2)/(O17:XFD17<>""), O17:XFD17),"Not Submitted")} -> Cat. -IV | Q17: Cat. -IV | S17: Document received by Mr. Samrej Vahora on 23.02.2026 | BM17: =MID(F17,20,1) -> E
A18: 16 | B18: =$A$1 -> PSS10B_Adani Renewable Energy 35 Limited (ARE35L) | C18: Battery | D18: Vendor | E18: Jinco | F18: 51N2-JNCO-BTR-BCL-DE-G-0001 | G18: 51H2-E-BTR-BAR-DE-D-V-0001 | H18: General Arrangement (GA) drawing for cell | I18: Information | J18: Document | K18: 46052 | N18: {=_xlfn.IFNA(LOOKUP(2, 1/(MOD(COLUMN(O18:XFD18)-COLUMN(O18), 5)=2)/(O18:XFD18<>""), O18:XFD18),"Not Submitted")} -> Cat. -IV | Q18: Cat. -IV | S18: Document received by Mr. Samrej Vahora on 23.02.2026 | BM18: =MID(F18,20,1) -> E
A19: 17 | B19: =$A$1 -> PSS10B_Adani Renewable Energy 35 Limited (ARE35L) | C19: Battery | D19: Vendor | E19: Jinco | F19: 51N2-JNCO-BTR-BCL-DE-R-0001 | G19: 51H2-E-BTR-BAR-DE-G-V-0001 | H19: Battery cell certification and compliance report, including detailed model numbers and test results for cell | I19: Information | J19: Drawing | K19: 46052 | N19: {=_xlfn.IFNA(LOOKUP(2, 1/(MOD(COLUMN(O19:XFD19)-COLUMN(O19), 5)=2)/(O19:XFD19<>""), O19:XFD19),"Not Submitted")} -> Cat. -IV | Q19: Cat. -IV | S19: Document received by Mr. Samrej Vahora on 23.02.2026 | BM19: =MID(F19,20,1) -> E
A20: 18 | B20: =$A$1 -> PSS10B_Adani Renewable Energy 35 Limited (ARE35L) | C20: Battery | D20: Vendor | E20: Jinco | F20: 51N2-JNCO-BTR-BAR-DE-D-0001 | G20: 51H2-E-BTR-BAR-BE-R-V-0001 | H20: GTP (Technical Paramater detail) (Pack, HV box and rack ) for rack | I20: Approval | J20: Document | K20: 46052 | N20: {=_xlfn.IFNA(LOOKUP(2, 1/(MOD(COLUMN(O20:XFD20)-COLUMN(O20), 5)=2)/(O20:XFD20<>""), O20:XFD20),"Not Submitted")} -> Cat. -I | Q20: Cat. -I | S20: Document received by Mr. Samrej Vahora on 23.02.2026 | BM20: =MID(F20,20,1) -> E
A21: 19 | B21: =$A$1 -> PSS10B_Adani Renewable Energy 35 Limited (ARE35L) | C21: Battery | D21: Vendor | E21: Jinco | F21: 51N2-JNCO-BTR-BAR-DE-G-0001 | G21: 51H2-E-BTR-BCN-DE-D-V-0001 | H21: GA Drawing (PDF &CAD file ) showing component layout and dimensions for rack 1- Battery Pack 2- HV box with Rack Frame | I21: Approval | J21: Document | K21: 46052 | N21: {=_xlfn.IFNA(LOOKUP(2, 1/(MOD(COLUMN(O21:XFD21)-COLUMN(O21), 5)=2)/(O21:XFD21<>""), O21:XFD21),"Not Submitted")} -> Cat. -I | Q21: Cat. -I | S21: Document received by Mr. Samrej Vahora on 23.02.2026 | BM21: =MID(F21,20,1) -> E
A22: 20 | B22: =$A$1 -> PSS10B_Adani Renewable Energy 35 Limited (ARE35L) | C22: Battery | D22: Vendor | E22: Jinco | F22: 51N2-JNCO-BTR-BAR-DE-R-0001 | G22: 51H2-E-BTR-BCN-DE-G-V-0001 | H22: Certification and test report for battery rack, including model numbers and compliance data for rack | I22: Information | J22: Drawing | K22: 46052 | N22: {=_xlfn.IFNA(LOOKUP(2, 1/(MOD(COLUMN(O22:XFD22)-COLUMN(O22), 5)=2)/(O22:XFD22<>""), O22:XFD22),"Not Submitted")} -> Cat. -IV | Q22: Cat. -IV | S22: Document received by Mr. Samrej Vahora on 23.02.2026 | BM22: =MID(F22,20,1) -> E
